Workbook

Sheet Instructions
A1: Instructions:
A3: 1. Pick one of the orange tabs that has not been filled in already
A4: 2. Follow the instructions on that orange tab
A5: 3. Once all team members have filled their respective orange tabs, check the 'Team Availablity' tab
A6: and change the time zone value in that 'Team Availability' tab to your time zone to see team availability in your time zone

Sheet Aaron Reimer
A1: Step 1: Rename the sheet name with your name, for example 'Member 1 Name' to 'Your Name' | J1: Time Zone
A2: Step 2: Choose your time zone from yellow drop down box | J2: PST
A3: Step 3: Enter '1' in all 30-minute slots you're NOT available in orange area | J3: {=_xlfn.SWITCH(J2,"PST",0,"MST",1,"CST",2,"EST",3,0)} -> 0
A6: Time | B6: Monday | C6: Tuesday | D6: Wednesday | E6: Thursday | F6: Friday | G6: Saturday | H6: Sunday
A7: =TEXT(TIME(3,0,0)+$J$3/24,"h:mm AM/PM") & " - " & TEXT(TIME(3,30,0)+$J$3/24,"h:mm AM/PM") -> 3:00 AM - 3:30 AM | B7: 1 | C7: 1 | D7: 1 | E7: 1 | F7: 1 | G7: 1 | H7: 1
A8: =TEXT(TIMEVALUE(LEFT(A7,FIND(" -",A7)-1))+TIME(0,30,0), "h:mm AM/PM") & " - " & TEXT(TIMEVALUE(MID(A7,FIND("- ",A7)+2,99))+TIME(0,30,0), "h:mm AM/PM") -> 3:30 AM - 4:00 AM | B8: 1 | C8: 1 | D8: 1 | E8: 1 | F8: 1 | G8: 1 | H8: 1
A9: =TEXT(TIMEVALUE(LEFT(A8,FIND(" -",A8)-1))+TIME(0,30,0), "h:mm AM/PM") & " - " & TEXT(TIMEVALUE(MID(A8,FIND("- ",A8)+2,99))+TIME(0,30,0), "h:mm AM/PM") -> 4:00 AM - 4:30 AM | B9: 1 | C9: 1 | D9: 1 | E9: 1 | F9: 1 | G9: 1 | H9: 1
A10: =TEXT(TIMEVALUE(LEFT(A9,FIND(" -",A9)-1))+TIME(0,30,0), "h:mm AM/PM") & " - " & TEXT(TIMEVALUE(MID(A9,FIND("- ",A9)+2,99))+TIME(0,30,0), "h:mm AM/PM") -> 4:30 AM - 5:00 AM | B10: 1 | C10: 1 | D10: 1 | E10: 1 | F10: 1 | G10: 1 | H10: 1
A11: =TEXT(TIMEVALUE(LEFT(A10,FIND(" -",A10)-1))+TIME(0,30,0), "h:mm AM/PM") & " - " & TEXT(TIMEVALUE(MID(A10,FIND("- ",A10)+2,99))+TIME(0,30,0), "h:mm AM/PM") -> 5:00 AM - 5:30 AM | B11: 1 | C11: 1 | D11: 1 | E11: 1 | F11: 1 | G11: 1 | H11: 1
A12: =TEXT(TIMEVALUE(LEFT(A11,FIND(" -",A11)-1))+TIME(0,30,0), "h:mm AM/PM") & " - " & TEXT(TIMEVALUE(MID(A11,FIND("- ",A11)+2,99))+TIME(0,30,0), "h:mm AM/PM") -> 5:30 AM - 6:00 AM | B12: 1 | C12: 1 | D12: 1 | E12: 1 | F12: 1 | G12: 1 | H12: 1
A13: =TEXT(TIMEVALUE(LEFT(A12,FIND(" -",A12)-1))+TIME(0,30,0), "h:mm AM/PM") & " - " & TEXT(TIMEVALUE(MID(A12,FIND("- ",A12)+2,99))+TIME(0,30,0), "h:mm AM/PM") -> 6:00 AM - 6:30 AM | B13: 1 | C13: 1 | D13: 1 | E13: 1 | F13: 1 | G13: 1 | H13: 1
A14: =TEXT(TIMEVALUE(LEFT(A13,FIND(" -",A13)-1))+TIME(0,30,0), "h:mm AM/PM") & " - " & TEXT(TIMEVALUE(MID(A13,FIND("- ",A13)+2,99))+TIME(0,30,0), "h:mm AM/PM") -> 6:30 AM - 7:00 AM | B14: 1 | C14: 1 | D14: 1 | E14: 1 | F14: 1 | G14: 1 | H14: 1
A15: =TEXT(TIMEVALUE(LEFT(A14,FIND(" -",A14)-1))+TIME(0,30,0), "h:mm AM/PM") & " - " & TEXT(TIMEVALUE(MID(A14,FIND("- ",A14)+2,99))+TIME(0,30,0), "h:mm AM/PM") -> 7:00 AM - 7:30 AM | B15: 1 | C15: 1 | D15: 1 | E15: 1 | F15: 1 | G15: 1 | H15: 1
A16: =TEXT(TIMEVALUE(LEFT(A15,FIND(" -",A15)-1))+TIME(0,30,0), "h:mm AM/PM") & " - " & TEXT(TIMEVALUE(MID(A15,FIND("- ",A15)+2,99))+TIME(0,30,0), "h:mm AM/PM") -> 7:30 AM - 8:00 AM | B16: 1 | C16: 1 | D16: 1 | E16: 1 | F16: 1 | G16: 1 | H16: 1
A17: =TEXT(TIMEVALUE(LEFT(A16,FIND(" -",A16)-1))+TIME(0,30,0), "h:mm AM/PM") & " - " & TEXT(TIMEVALUE(MID(A16,FIND("- ",A16)+2,99))+TIME(0,30,0), "h:mm AM/PM") -> 8:00 AM - 8:30 AM | B17: 1 | C17: 1 | D17: 1 | E17: 1 | F17: 1 | G17: 1 | H17: 1
A18: =TEXT(TIMEVALUE(LEFT(A17,FIND(" -",A17)-1))+TIME(0,30,0), "h:mm AM/PM") & " - " & TEXT(TIMEVALUE(MID(A17,FIND("- ",A17)+2,99))+TIME(0,30,0), "h:mm AM/PM") -> 8:30 AM - 9:00 AM | B18: 1 | C18: 1 | D18: 1 | E18: 1 | F18: 1 | G18: 1 | H18: 1
A19: =TEXT(TIMEVALUE(LEFT(A18,FIND(" -",A18)-1))+TIME(0,30,0), "h:mm AM/PM") & " - " & TEXT(TIMEVALUE(MID(A18,FIND("- ",A18)+2,99))+TIME(0,30,0), "h:mm AM/PM") -> 9:00 AM - 9:30 AM
A20: =TEXT(TIMEVALUE(LEFT(A19,FIND(" -",A19)-1))+TIME(0,30,0), "h:mm AM/PM") & " - " & TEXT(TIMEVALUE(MID(A19,FIND("- ",A19)+2,99))+TIME(0,30,0), "h:mm AM/PM") -> 9:30 AM - 10:00 AM
A21: =TEXT(TIMEVALUE(LEFT(A20,FIND(" -",A20)-1))+TIME(0,30,0), "h:mm AM/PM") & " - " & TEXT(TIMEVALUE(MID(A20,FIND("- ",A20)+2,99))+TIME(0,30,0), "h:mm AM/PM") -> 10:00 AM - 10:30 AM
A22: =TEXT(TIMEVALUE(LEFT(A21,FIND(" -",A21)-1))+TIME(0,30,0), "h:mm AM/PM") & " - " & TEXT(TIMEVALUE(MID(A21,FIND("- ",A21)+2,99))+TIME(0,30,0), "h:mm AM/PM") -> 10:30 AM - 11:00 AM
A23: =TEXT(TIMEVALUE(LEFT(A22,FIND(" -",A22)-1))+TIME(0,30,0), "h:mm AM/PM") & " - " & TEXT(TIMEVALUE(MID(A22,FIND("- ",A22)+2,99))+TIME(0,30,0), "h:mm AM/PM") -> 11:00 AM - 11:30 AM
A24: =TEXT(TIMEVALUE(LEFT(A23,FIND(" -",A23)-1))+TIME(0,30,0), "h:mm AM/PM") & " - " & TEXT(TIMEVALUE(MID(A23,FIND("- ",A23)+2,99))+TIME(0,30,0), "h:mm AM/PM") -> 11:30 AM - 12:00 PM
A25: =TEXT(TIMEVALUE(LEFT(A24,FIND(" -",A24)-1))+TIME(0,30,0), "h:mm AM/PM") & " - " & TEXT(TIMEVALUE(MID(A24,FIND("- ",A24)+2,99))+TIME(0,30,0), "h:mm AM/PM") -> 12:00 PM - 12:30 PM
A26: =TEXT(TIMEVALUE(LEFT(A25,FIND(" -",A25)-1))+TIME(0,30,0), "h:mm AM/PM") & " - " & TEXT(TIMEVALUE(MID(A25,FIND("- ",A25)+2,99))+TIME(0,30,0), "h:mm AM/PM") -> 12:30 PM - 1:00 PM
A27: =TEXT(TIMEVALUE(LEFT(A26,FIND(" -",A26)-1))+TIME(0,30,0), "h:mm AM/PM") & " - " & TEXT(TIMEVALUE(MID(A26,FIND("- ",A26)+2,99))+TIME(0,30,0), "h:mm AM/PM") -> 1:00 PM - 1:30 PM
A28: =TEXT(TIMEVALUE(LEFT(A27,FIND(" -",A27)-1))+TIME(0,30,0), "h:mm AM/PM") & " - " & TEXT(TIMEVALUE(MID(A27,FIND("- ",A27)+2,99))+TIME(0,30,0), "h:mm AM/PM") -> 1:30 PM - 2:00 PM
A29: =TEXT(TIMEVALUE(LEFT(A28,FIND(" -",A28)-1))+TIME(0,30,0), "h:mm AM/PM") & " - " & TEXT(TIMEVALUE(MID(A28,FIND("- ",A28)+2,99))+TIME(0,30,0), "h:mm AM/PM") -> 2:00 PM - 2:30 PM
A30: =TEXT(TIMEVALUE(LEFT(A29,FIND(" -",A29)-1))+TIME(0,30,0), "h:mm AM/PM") & " - " & TEXT(TIMEVALUE(MID(A29,FIND("- ",A29)+2,99))+TIME(0,30,0), "h:mm AM/PM") -> 2:30 PM - 3:00 PM
... A34: =TEXT(TIMEVALUE(LEFT(A33,FIND(" -",A33)-1))+TIME(0,30,0), "h:mm AM/PM") & " - " & TEXT(TIMEVALUE(MID(A33,FIND("- ",A33)+2,99))+TIME(0,30,0), "h:mm AM/PM") -> 4:30 PM - 5:00 PM
A35: =TEXT(TIMEVALUE(LEFT(A34,FIND(" -",A34)-1))+TIME(0,30,0), "h:mm AM/PM") & " - " & TEXT(TIMEVALUE(MID(A34,FIND("- ",A34)+2,99))+TIME(0,30,0), "h:mm AM/PM") -> 5:00 PM - 5:30 PM | B35: 1 | C35: 1 | D35: 1 | E35: 1 | F35: 1 | G35: 1 | H35: 1
A36: =TEXT(TIMEVALUE(LEFT(A35,FIND(" -",A35)-1))+TIME(0,30,0), "h:mm AM/PM") & " - " & TEXT(TIMEVALUE(MID(A35,FIND("- ",A35)+2,99))+TIME(0,30,0), "h:mm AM/PM") -> 5:30 PM - 6:00 PM | B36: 1 | C36: 1 | D36: 1 | E36: 1 | F36: 1 | G36: 1 | H36: 1
A37: =TEXT(TIMEVALUE(LEFT(A36,FIND(" -",A36)-1))+TIME(0,30,0), "h:mm AM/PM") & " - " & TEXT(TIMEVALUE(MID(A36,FIND("- ",A36)+2,99))+TIME(0,30,0), "h:mm AM/PM") -> 6:00 PM - 6:30 PM | B37: 1 | C37: 1 | D37: 1 | E37: 1 | F37: 1 | G37: 1 | H37: 1
A38: =TEXT(TIMEVALUE(LEFT(A37,FIND(" -",A37)-1))+TIME(0,30,0), "h:mm AM/PM") & " - " & TEXT(TIMEVALUE(MID(A37,FIND("- ",A37)+2,99))+TIME(0,30,0), "h:mm AM/PM") -> 6:30 PM - 7:00 PM | B38: 1 | C38: 1 | D38: 1 | E38: 1 | F38: 1 | G38: 1 | H38: 1
A39: =TEXT(TIMEVALUE(LEFT(A38,FIND(" -",A38)-1))+TIME(0,30,0), "h:mm AM/PM") & " - " & TEXT(TIMEVALUE(MID(A38,FIND("- ",A38)+2,99))+TIME(0,30,0), "h:mm AM/PM") -> 7:00 PM - 7:30 PM | B39: 1 | C39: 1 | D39: 1 | E39: 1 | F39: 1 | G39: 1 | H39: 1
A40: =TEXT(TIMEVALUE(LEFT(A39,FIND(" -",A39)-1))+TIME(0,30,0), "h:mm AM/PM") & " - " & TEXT(TIMEVALUE(MID(A39,FIND("- ",A39)+2,99))+TIME(0,30,0), "h:mm AM/PM") -> 7:30 PM - 8:00 PM | B40: 1 | C40: 1 | D40: 1 | E40: 1 | F40: 1 | G40: 1 | H40: 1
A41: =TEXT(TIMEVALUE(LEFT(A40,FIND(" -",A40)-1))+TIME(0,30,0), "h:mm AM/PM") & " - " & TEXT(TIMEVALUE(MID(A40,FIND("- ",A40)+2,99))+TIME(0,30,0), "h:mm AM/PM") -> 8:00 PM - 8:30 PM | B41: 1 | C41: 1 | D41: 1 | E41: 1 | F41: 1 | G41: 1 | H41: 1
A42: =TEXT(TIMEVALUE(LEFT(A41,FIND(" -",A41)-1))+TIME(0,30,0), "h:mm AM/PM") & " - " & TEXT(TIMEVALUE(MID(A41,FIND("- ",A41)+2,99))+TIME(0,30,0), "h:mm AM/PM") -> 8:30 PM - 9:00 PM | B42: 1 | C42: 1 | D42: 1 | E42: 1 | F42: 1 | G42: 1 | H42: 1
A43: =TEXT(TIMEVALUE(LEFT(A42,FIND(" -",A42)-1))+TIME(0,30,0), "h:mm AM/PM") & " - " & TEXT(TIMEVALUE(MID(A42,FIND("- ",A42)+2,99))+TIME(0,30,0), "h:mm AM/PM") -> 9:00 PM - 9:30 PM | B43: 1 | C43: 1 | D43: 1 | E43: 1 | F43: 1 | G43: 1 | H43: 1

Sheet Sruti Dondapati
A1: Step 1: Rename the sheet name with your name, for example 'Member 2 Name' to 'Your Name' | J1: Time Zone
A2: Step 2: Choose your time zone from yellow drop down box | J2: PST
A3: Step 3: Enter '1' in all 30-minute slots you're NOT available in orange area | J3: {=_xlfn.SWITCH(J2,"PST",0,"MST",1,"CST",2,"EST",3,0)} -> 0
A6: Time | B6: Monday | C6: Tuesday | D6: Wednesday | E6: Thursday | F6: Friday | G6: Saturday | H6: Sunday
A7: =TEXT(TIME(3,0,0)+$J$3/24,"h:mm AM/PM") & " - " & TEXT(TIME(3,30,0)+$J$3/24,"h:mm AM/PM") -> 3:00 AM - 3:30 AM | B7: 1 | C7: 1 | D7: 1 | E7: 1 | F7: 1 | G7: 1 | H7: 1
A8: =TEXT(TIMEVALUE(LEFT(A7,FIND(" -",A7)-1))+TIME(0,30,0), "h:mm AM/PM") & " - " & TEXT(TIMEVALUE(MID(A7,FIND("- ",A7)+2,99))+TIME(0,30,0), "h:mm AM/PM") -> 3:30 AM - 4:00 AM | B8: 1 | C8: 1 | D8: 1 | E8: 1 | F8: 1 | G8: 1 | H8: 1
A9: =TEXT(TIMEVALUE(LEFT(A8,FIND(" -",A8)-1))+TIME(0,30,0), "h:mm AM/PM") & " - " & TEXT(TIMEVALUE(MID(A8,FIND("- ",A8)+2,99))+TIME(0,30,0), "h:mm AM/PM") -> 4:00 AM - 4:30 AM | B9: 1 | C9: 1 | D9: 1 | E9: 1 | F9: 1 | G9: 1 | H9: 1
A10: =TEXT(TIMEVALUE(LEFT(A9,FIND(" -",A9)-1))+TIME(0,30,0), "h:mm AM/PM") & " - " & TEXT(TIMEVALUE(MID(A9,FIND("- ",A9)+2,99))+TIME(0,30,0), "h:mm AM/PM") -> 4:30 AM - 5:00 AM | B10: 1 | C10: 1 | D10: 1 | E10: 1 | F10: 1 | G10: 1 | H10: 1
A11: =TEXT(TIMEVALUE(LEFT(A10,FIND(" -",A10)-1))+TIME(0,30,0), "h:mm AM/PM") & " - " & TEXT(TIMEVALUE(MID(A10,FIND("- ",A10)+2,99))+TIME(0,30,0), "h:mm AM/PM") -> 5:00 AM - 5:30 AM | B11: 1 | C11: 1 | D11: 1 | E11: 1 | F11: 1 | G11: 1 | H11: 1
A12: =TEXT(TIMEVALUE(LEFT(A11,FIND(" -",A11)-1))+TIME(0,30,0), "h:mm AM/PM") & " - " & TEXT(TIMEVALUE(MID(A11,FIND("- ",A11)+2,99))+TIME(0,30,0), "h:mm AM/PM") -> 5:30 AM - 6:00 AM | B12: 1 | C12: 1 | D12: 1 | E12: 1 | F12: 1 | G12: 1 | H12: 1
A13: =TEXT(TIMEVALUE(LEFT(A12,FIND(" -",A12)-1))+TIME(0,30,0), "h:mm AM/PM") & " - " & TEXT(TIMEVALUE(MID(A12,FIND("- ",A12)+2,99))+TIME(0,30,0), "h:mm AM/PM") -> 6:00 AM - 6:30 AM | B13: 1 | C13: 1 | D13: 1 | E13: 1 | F13: 1 | G13: 1 | H13: 1
A14: =TEXT(TIMEVALUE(LEFT(A13,FIND(" -",A13)-1))+TIME(0,30,0), "h:mm AM/PM") & " - " & TEXT(TIMEVALUE(MID(A13,FIND("- ",A13)+2,99))+TIME(0,30,0), "h:mm AM/PM") -> 6:30 AM - 7:00 AM | B14: 1 | C14: 1 | D14: 1 | E14: 1 | F14: 1 | G14: 1 | H14: 1
A15: =TEXT(TIMEVALUE(LEFT(A14,FIND(" -",A14)-1))+TIME(0,30,0), "h:mm AM/PM") & " - " & TEXT(TIMEVALUE(MID(A14,FIND("- ",A14)+2,99))+TIME(0,30,0), "h:mm AM/PM") -> 7:00 AM - 7:30 AM | B15: 1 | C15: 1 | D15: 1 | E15: 1 | F15: 1 | G15: 1 | H15: 1
A16: =TEXT(TIMEVALUE(LEFT(A15,FIND(" -",A15)-1))+TIME(0,30,0), "h:mm AM/PM") & " - " & TEXT(TIMEVALUE(MID(A15,FIND("- ",A15)+2,99))+TIME(0,30,0), "h:mm AM/PM") -> 7:30 AM - 8:00 AM | B16: 1 | C16: 1 | D16: 1 | E16: 1 | F16: 1 | G16: 1 | H16: 1
A17: =TEXT(TIMEVALUE(LEFT(A16,FIND(" -",A16)-1))+TIME(0,30,0), "h:mm AM/PM") & " - " & TEXT(TIMEVALUE(MID(A16,FIND("- ",A16)+2,99))+TIME(0,30,0), "h:mm AM/PM") -> 8:00 AM - 8:30 AM | B17: 1 | C17: 1 | D17: 1 | E17: 1 | F17: 1 | G17: 1 | H17: 1
A18: =TEXT(TIMEVALUE(LEFT(A17,FIND(" -",A17)-1))+TIME(0,30,0), "h:mm AM/PM") & " - " & TEXT(TIMEVALUE(MID(A17,FIND("- ",A17)+2,99))+TIME(0,30,0), "h:mm AM/PM") -> 8:30 AM - 9:00 AM | B18: 1 | C18: 1 | D18: 1 | E18: 1 | F18: 1 | G18: 1 | H18: 1
A19: =TEXT(TIMEVALUE(LEFT(A18,FIND(" -",A18)-1))+TIME(0,30,0), "h:mm AM/PM") & " - " & TEXT(TIMEVALUE(MID(A18,FIND("- ",A18)+2,99))+TIME(0,30,0), "h:mm AM/PM") -> 9:00 AM - 9:30 AM | B19: 1 | C19: 1 | D19: 1 | E19: 1 | F19: 1 | G19: 1 | H19: 1
A20: =TEXT(TIMEVALUE(LEFT(A19,FIND(" -",A19)-1))+TIME(0,30,0), "h:mm AM/PM") & " - " & TEXT(TIMEVALUE(MID(A19,FIND("- ",A19)+2,99))+TIME(0,30,0), "h:mm AM/PM") -> 9:30 AM - 10:00 AM
A21: =TEXT(TIMEVALUE(LEFT(A20,FIND(" -",A20)-1))+TIME(0,30,0), "h:mm AM/PM") & " - " & TEXT(TIMEVALUE(MID(A20,FIND("- ",A20)+2,99))+TIME(0,30,0), "h:mm AM/PM") -> 10:00 AM - 10:30 AM
A22: =TEXT(TIMEVALUE(LEFT(A21,FIND(" -",A21)-1))+TIME(0,30,0), "h:mm AM/PM") & " - " & TEXT(TIMEVALUE(MID(A21,FIND("- ",A21)+2,99))+TIME(0,30,0), "h:mm AM/PM") -> 10:30 AM - 11:00 AM
A23: =TEXT(TIMEVALUE(LEFT(A22,FIND(" -",A22)-1))+TIME(0,30,0), "h:mm AM/PM") & " - " & TEXT(TIMEVALUE(MID(A22,FIND("- ",A22)+2,99))+TIME(0,30,0), "h:mm AM/PM") -> 11:00 AM - 11:30 AM
A24: =TEXT(TIMEVALUE(LEFT(A23,FIND(" -",A23)-1))+TIME(0,30,0), "h:mm AM/PM") & " - " & TEXT(TIMEVALUE(MID(A23,FIND("- ",A23)+2,99))+TIME(0,30,0), "h:mm AM/PM") -> 11:30 AM - 12:00 PM
A25: =TEXT(TIMEVALUE(LEFT(A24,FIND(" -",A24)-1))+TIME(0,30,0), "h:mm AM/PM") & " - " & TEXT(TIMEVALUE(MID(A24,FIND("- ",A24)+2,99))+TIME(0,30,0), "h:mm AM/PM") -> 12:00 PM - 12:30 PM
A26: =TEXT(TIMEVALUE(LEFT(A25,FIND(" -",A25)-1))+TIME(0,30,0), "h:mm AM/PM") & " - " & TEXT(TIMEVALUE(MID(A25,FIND("- ",A25)+2,99))+TIME(0,30,0), "h:mm AM/PM") -> 12:30 PM - 1:00 PM
A27: =TEXT(TIMEVALUE(LEFT(A26,FIND(" -",A26)-1))+TIME(0,30,0), "h:mm AM/PM") & " - " & TEXT(TIMEVALUE(MID(A26,FIND("- ",A26)+2,99))+TIME(0,30,0), "h:mm AM/PM") -> 1:00 PM - 1:30 PM
A28: =TEXT(TIMEVALUE(LEFT(A27,FIND(" -",A27)-1))+TIME(0,30,0), "h:mm AM/PM") & " - " & TEXT(TIMEVALUE(MID(A27,FIND("- ",A27)+2,99))+TIME(0,30,0), "h:mm AM/PM") -> 1:30 PM - 2:00 PM
A29: =TEXT(TIMEVALUE(LEFT(A28,FIND(" -",A28)-1))+TIME(0,30,0), "h:mm AM/PM") & " - " & TEXT(TIMEVALUE(MID(A28,FIND("- ",A28)+2,99))+TIME(0,30,0), "h:mm AM/PM") -> 2:00 PM - 2:30 PM
A30: =TEXT(TIMEVALUE(LEFT(A29,FIND(" -",A29)-1))+TIME(0,30,0), "h:mm AM/PM") & " - " & TEXT(TIMEVALUE(MID(A29,FIND("- ",A29)+2,99))+TIME(0,30,0), "h:mm AM/PM") -> 2:30 PM - 3:00 PM
A31: =TEXT(TIMEVALUE(LEFT(A30,FIND(" -",A30)-1))+TIME(0,30,0), "h:mm AM/PM") & " - " & TEXT(TIMEVALUE(MID(A30,FIND("- ",A30)+2,99))+TIME(0,30,0), "h:mm AM/PM") -> 3:00 PM - 3:30 PM
... A38: =TEXT(TIMEVALUE(LEFT(A37,FIND(" -",A37)-1))+TIME(0,30,0), "h:mm AM/PM") & " - " & TEXT(TIMEVALUE(MID(A37,FIND("- ",A37)+2,99))+TIME(0,30,0), "h:mm AM/PM") -> 6:30 PM - 7:00 PM
A39: =TEXT(TIMEVALUE(LEFT(A38,FIND(" -",A38)-1))+TIME(0,30,0), "h:mm AM/PM") & " - " & TEXT(TIMEVALUE(MID(A38,FIND("- ",A38)+2,99))+TIME(0,30,0), "h:mm AM/PM") -> 7:00 PM - 7:30 PM | B39: 1 | C39: 1 | D39: 1 | E39: 1 | F39: 1 | G39: 1 | H39: 1
A40: =TEXT(TIMEVALUE(LEFT(A39,FIND(" -",A39)-1))+TIME(0,30,0), "h:mm AM/PM") & " - " & TEXT(TIMEVALUE(MID(A39,FIND("- ",A39)+2,99))+TIME(0,30,0), "h:mm AM/PM") -> 7:30 PM - 8:00 PM | B40: 1 | C40: 1 | D40: 1 | E40: 1 | F40: 1 | G40: 1 | H40: 1
A41: =TEXT(TIMEVALUE(LEFT(A40,FIND(" -",A40)-1))+TIME(0,30,0), "h:mm AM/PM") & " - " & TEXT(TIMEVALUE(MID(A40,FIND("- ",A40)+2,99))+TIME(0,30,0), "h:mm AM/PM") -> 8:00 PM - 8:30 PM | B41: 1 | C41: 1 | D41: 1 | E41: 1 | F41: 1 | G41: 1 | H41: 1
A42: =TEXT(TIMEVALUE(LEFT(A41,FIND(" -",A41)-1))+TIME(0,30,0), "h:mm AM/PM") & " - " & TEXT(TIMEVALUE(MID(A41,FIND("- ",A41)+2,99))+TIME(0,30,0), "h:mm AM/PM") -> 8:30 PM - 9:00 PM | B42: 1 | C42: 1 | D42: 1 | E42: 1 | F42: 1 | G42: 1 | H42: 1
A43: =TEXT(TIMEVALUE(LEFT(A42,FIND(" -",A42)-1))+TIME(0,30,0), "h:mm AM/PM") & " - " & TEXT(TIMEVALUE(MID(A42,FIND("- ",A42)+2,99))+TIME(0,30,0), "h:mm AM/PM") -> 9:00 PM - 9:30 PM | B43: 1 | C43: 1 | D43: 1 | E43: 1 | F43: 1 | G43: 1 | H43: 1

Sheet Member 3 Name
A1: Step 1: Rename the sheet name with your name, for example 'Member 3 Name' to 'Your Name' | J1: Time Zone
A2: Step 2: Choose your time zone from yellow drop down box | J2: PST
A3: Step 3: Enter '1' in all 30-minute slots you're NOT available in orange area | J3: {=_xlfn.SWITCH(J2,"PST",0,"MST",1,"CST",2,"EST",3,0)} -> 0
A6: Time | B6: Monday | C6: Tuesday | D6: Wednesday | E6: Thursday | F6: Friday | G6: Saturday | H6: Sunday
A7: =TEXT(TIME(3,0,0)+$J$3/24,"h:mm AM/PM") & " - " & TEXT(TIME(3,30,0)+$J$3/24,"h:mm AM/PM") -> 3:00 AM - 3:30 AM
A8: =TEXT(TIMEVALUE(LEFT(A7,FIND(" -",A7)-1))+TIME(0,30,0), "h:mm AM/PM") & " - " & TEXT(TIMEVALUE(MID(A7,FIND("- ",A7)+2,99))+TIME(0,30,0), "h:mm AM/PM") -> 3:30 AM - 4:00 AM
A9: =TEXT(TIMEVALUE(LEFT(A8,FIND(" -",A8)-1))+TIME(0,30,0), "h:mm AM/PM") & " - " & TEXT(TIMEVALUE(MID(A8,FIND("- ",A8)+2,99))+TIME(0,30,0), "h:mm AM/PM") -> 4:00 AM - 4:30 AM
A10: =TEXT(TIMEVALUE(LEFT(A9,FIND(" -",A9)-1))+TIME(0,30,0), "h:mm AM/PM") & " - " & TEXT(TIMEVALUE(MID(A9,FIND("- ",A9)+2,99))+TIME(0,30,0), "h:mm AM/PM") -> 4:30 AM - 5:00 AM
A11: =TEXT(TIMEVALUE(LEFT(A10,FIND(" -",A10)-1))+TIME(0,30,0), "h:mm AM/PM") & " - " & TEXT(TIMEVALUE(MID(A10,FIND("- ",A10)+2,99))+TIME(0,30,0), "h:mm AM/PM") -> 5:00 AM - 5:30 AM
A12: =TEXT(TIMEVALUE(LEFT(A11,FIND(" -",A11)-1))+TIME(0,30,0), "h:mm AM/PM") & " - " & TEXT(TIMEVALUE(MID(A11,FIND("- ",A11)+2,99))+TIME(0,30,0), "h:mm AM/PM") -> 5:30 AM - 6:00 AM
A13: =TEXT(TIMEVALUE(LEFT(A12,FIND(" -",A12)-1))+TIME(0,30,0), "h:mm AM/PM") & " - " & TEXT(TIMEVALUE(MID(A12,FIND("- ",A12)+2,99))+TIME(0,30,0), "h:mm AM/PM") -> 6:00 AM - 6:30 AM
A14: =TEXT(TIMEVALUE(LEFT(A13,FIND(" -",A13)-1))+TIME(0,30,0), "h:mm AM/PM") & " - " & TEXT(TIMEVALUE(MID(A13,FIND("- ",A13)+2,99))+TIME(0,30,0), "h:mm AM/PM") -> 6:30 AM - 7:00 AM
A15: =TEXT(TIMEVALUE(LEFT(A14,FIND(" -",A14)-1))+TIME(0,30,0), "h:mm AM/PM") & " - " & TEXT(TIMEVALUE(MID(A14,FIND("- ",A14)+2,99))+TIME(0,30,0), "h:mm AM/PM") -> 7:00 AM - 7:30 AM
A16: =TEXT(TIMEVALUE(LEFT(A15,FIND(" -",A15)-1))+TIME(0,30,0), "h:mm AM/PM") & " - " & TEXT(TIMEVALUE(MID(A15,FIND("- ",A15)+2,99))+TIME(0,30,0), "h:mm AM/PM") -> 7:30 AM - 8:00 AM
A17: =TEXT(TIMEVALUE(LEFT(A16,FIND(" -",A16)-1))+TIME(0,30,0), "h:mm AM/PM") & " - " & TEXT(TIMEVALUE(MID(A16,FIND("- ",A16)+2,99))+TIME(0,30,0), "h:mm AM/PM") -> 8:00 AM - 8:30 AM
A18: =TEXT(TIMEVALUE(LEFT(A17,FIND(" -",A17)-1))+TIME(0,30,0), "h:mm AM/PM") & " - " & TEXT(TIMEVALUE(MID(A17,FIND("- ",A17)+2,99))+TIME(0,30,0), "h:mm AM/PM") -> 8:30 AM - 9:00 AM
A19: =TEXT(TIMEVALUE(LEFT(A18,FIND(" -",A18)-1))+TIME(0,30,0), "h:mm AM/PM") & " - " & TEXT(TIMEVALUE(MID(A18,FIND("- ",A18)+2,99))+TIME(0,30,0), "h:mm AM/PM") -> 9:00 AM - 9:30 AM
... A43: =TEXT(TIMEVALUE(LEFT(A42,FIND(" -",A42)-1))+TIME(0,30,0), "h:mm AM/PM") & " - " & TEXT(TIMEVALUE(MID(A42,FIND("- ",A42)+2,99))+TIME(0,30,0), "h:mm AM/PM") -> 9:00 PM - 9:30 PM

Sheet Member 4 Name
A1: Step 1: Rename the sheet name with your name, for example 'Member 4 Name' to 'Your Name' | J1: Time Zone
A2: Step 2: Choose your time zone from yellow drop down box | J2: PST
A3: Step 3: Enter '1' in all 30-minute slots you're NOT available in orange area | J3: {=_xlfn.SWITCH(J2,"PST",0,"MST",1,"CST",2,"EST",3,0)} -> 0
A6: Time | B6: Monday | C6: Tuesday | D6: Wednesday | E6: Thursday | F6: Friday | G6: Saturday | H6: Sunday
A7: =TEXT(TIME(3,0,0)+$J$3/24,"h:mm AM/PM") & " - " & TEXT(TIME(3,30,0)+$J$3/24,"h:mm AM/PM") -> 3:00 AM - 3:30 AM
A8: =TEXT(TIMEVALUE(LEFT(A7,FIND(" -",A7)-1))+TIME(0,30,0), "h:mm AM/PM") & " - " & TEXT(TIMEVALUE(MID(A7,FIND("- ",A7)+2,99))+TIME(0,30,0), "h:mm AM/PM") -> 3:30 AM - 4:00 AM
A9: =TEXT(TIMEVALUE(LEFT(A8,FIND(" -",A8)-1))+TIME(0,30,0), "h:mm AM/PM") & " - " & TEXT(TIMEVALUE(MID(A8,FIND("- ",A8)+2,99))+TIME(0,30,0), "h:mm AM/PM") -> 4:00 AM - 4:30 AM
A10: =TEXT(TIMEVALUE(LEFT(A9,FIND(" -",A9)-1))+TIME(0,30,0), "h:mm AM/PM") & " - " & TEXT(TIMEVALUE(MID(A9,FIND("- ",A9)+2,99))+TIME(0,30,0), "h:mm AM/PM") -> 4:30 AM - 5:00 AM
A11: =TEXT(TIMEVALUE(LEFT(A10,FIND(" -",A10)-1))+TIME(0,30,0), "h:mm AM/PM") & " - " & TEXT(TIMEVALUE(MID(A10,FIND("- ",A10)+2,99))+TIME(0,30,0), "h:mm AM/PM") -> 5:00 AM - 5:30 AM
A12: =TEXT(TIMEVALUE(LEFT(A11,FIND(" -",A11)-1))+TIME(0,30,0), "h:mm AM/PM") & " - " & TEXT(TIMEVALUE(MID(A11,FIND("- ",A11)+2,99))+TIME(0,30,0), "h:mm AM/PM") -> 5:30 AM - 6:00 AM
A13: =TEXT(TIMEVALUE(LEFT(A12,FIND(" -",A12)-1))+TIME(0,30,0), "h:mm AM/PM") & " - " & TEXT(TIMEVALUE(MID(A12,FIND("- ",A12)+2,99))+TIME(0,30,0), "h:mm AM/PM") -> 6:00 AM - 6:30 AM
A14: =TEXT(TIMEVALUE(LEFT(A13,FIND(" -",A13)-1))+TIME(0,30,0), "h:mm AM/PM") & " - " & TEXT(TIMEVALUE(MID(A13,FIND("- ",A13)+2,99))+TIME(0,30,0), "h:mm AM/PM") -> 6:30 AM - 7:00 AM
A15: =TEXT(TIMEVALUE(LEFT(A14,FIND(" -",A14)-1))+TIME(0,30,0), "h:mm AM/PM") & " - " & TEXT(TIMEVALUE(MID(A14,FIND("- ",A14)+2,99))+TIME(0,30,0), "h:mm AM/PM") -> 7:00 AM - 7:30 AM
A16: =TEXT(TIMEVALUE(LEFT(A15,FIND(" -",A15)-1))+TIME(0,30,0), "h:mm AM/PM") & " - " & TEXT(TIMEVALUE(MID(A15,FIND("- ",A15)+2,99))+TIME(0,30,0), "h:mm AM/PM") -> 7:30 AM - 8:00 AM
A17: =TEXT(TIMEVALUE(LEFT(A16,FIND(" -",A16)-1))+TIME(0,30,0), "h:mm AM/PM") & " - " & TEXT(TIMEVALUE(MID(A16,FIND("- ",A16)+2,99))+TIME(0,30,0), "h:mm AM/PM") -> 8:00 AM - 8:30 AM
A18: =TEXT(TIMEVALUE(LEFT(A17,FIND(" -",A17)-1))+TIME(0,30,0), "h:mm AM/PM") & " - " & TEXT(TIMEVALUE(MID(A17,FIND("- ",A17)+2,99))+TIME(0,30,0), "h:mm AM/PM") -> 8:30 AM - 9:00 AM
A19: =TEXT(TIMEVALUE(LEFT(A18,FIND(" -",A18)-1))+TIME(0,30,0), "h:mm AM/PM") & " - " & TEXT(TIMEVALUE(MID(A18,FIND("- ",A18)+2,99))+TIME(0,30,0), "h:mm AM/PM") -> 9:00 AM - 9:30 AM
... A43: =TEXT(TIMEVALUE(LEFT(A42,FIND(" -",A42)-1))+TIME(0,30,0), "h:mm AM/PM") & " - " & TEXT(TIMEVALUE(MID(A42,FIND("- ",A42)+2,99))+TIME(0,30,0), "h:mm AM/PM") -> 9:00 PM - 9:30 PM

Sheet Member 5 Name
A1: Step 1: Rename the sheet name with your name, for example 'Member 5 Name' to 'Your Name' | J1: Time Zone
A2: Step 2: Choose your time zone from yellow drop down box | J2: PST
A3: Step 3: Enter '1' in all 30-minute slots you're NOT available in orange area | J3: {=_xlfn.SWITCH(J2,"PST",0,"MST",1,"CST",2,"EST",3,0)} -> 0
A6: Time | B6: Monday | C6: Tuesday | D6: Wednesday | E6: Thursday | F6: Friday | G6: Saturday | H6: Sunday
A7: =TEXT(TIME(3,0,0)+$J$3/24,"h:mm AM/PM") & " - " & TEXT(TIME(3,30,0)+$J$3/24,"h:mm AM/PM") -> 3:00 AM - 3:30 AM
A8: =TEXT(TIMEVALUE(LEFT(A7,FIND(" -",A7)-1))+TIME(0,30,0), "h:mm AM/PM") & " - " & TEXT(TIMEVALUE(MID(A7,FIND("- ",A7)+2,99))+TIME(0,30,0), "h:mm AM/PM") -> 3:30 AM - 4:00 AM
A9: =TEXT(TIMEVALUE(LEFT(A8,FIND(" -",A8)-1))+TIME(0,30,0), "h:mm AM/PM") & " - " & TEXT(TIMEVALUE(MID(A8,FIND("- ",A8)+2,99))+TIME(0,30,0), "h:mm AM/PM") -> 4:00 AM - 4:30 AM
A10: =TEXT(TIMEVALUE(LEFT(A9,FIND(" -",A9)-1))+TIME(0,30,0), "h:mm AM/PM") & " - " & TEXT(TIMEVALUE(MID(A9,FIND("- ",A9)+2,99))+TIME(0,30,0), "h:mm AM/PM") -> 4:30 AM - 5:00 AM
A11: =TEXT(TIMEVALUE(LEFT(A10,FIND(" -",A10)-1))+TIME(0,30,0), "h:mm AM/PM") & " - " & TEXT(TIMEVALUE(MID(A10,FIND("- ",A10)+2,99))+TIME(0,30,0), "h:mm AM/PM") -> 5:00 AM - 5:30 AM
A12: =TEXT(TIMEVALUE(LEFT(A11,FIND(" -",A11)-1))+TIME(0,30,0), "h:mm AM/PM") & " - " & TEXT(TIMEVALUE(MID(A11,FIND("- ",A11)+2,99))+TIME(0,30,0), "h:mm AM/PM") -> 5:30 AM - 6:00 AM
A13: =TEXT(TIMEVALUE(LEFT(A12,FIND(" -",A12)-1))+TIME(0,30,0), "h:mm AM/PM") & " - " & TEXT(TIMEVALUE(MID(A12,FIND("- ",A12)+2,99))+TIME(0,30,0), "h:mm AM/PM") -> 6:00 AM - 6:30 AM
A14: =TEXT(TIMEVALUE(LEFT(A13,FIND(" -",A13)-1))+TIME(0,30,0), "h:mm AM/PM") & " - " & TEXT(TIMEVALUE(MID(A13,FIND("- ",A13)+2,99))+TIME(0,30,0), "h:mm AM/PM") -> 6:30 AM - 7:00 AM
A15: =TEXT(TIMEVALUE(LEFT(A14,FIND(" -",A14)-1))+TIME(0,30,0), "h:mm AM/PM") & " - " & TEXT(TIMEVALUE(MID(A14,FIND("- ",A14)+2,99))+TIME(0,30,0), "h:mm AM/PM") -> 7:00 AM - 7:30 AM
A16: =TEXT(TIMEVALUE(LEFT(A15,FIND(" -",A15)-1))+TIME(0,30,0), "h:mm AM/PM") & " - " & TEXT(TIMEVALUE(MID(A15,FIND("- ",A15)+2,99))+TIME(0,30,0), "h:mm AM/PM") -> 7:30 AM - 8:00 AM
A17: =TEXT(TIMEVALUE(LEFT(A16,FIND(" -",A16)-1))+TIME(0,30,0), "h:mm AM/PM") & " - " & TEXT(TIMEVALUE(MID(A16,FIND("- ",A16)+2,99))+TIME(0,30,0), "h:mm AM/PM") -> 8:00 AM - 8:30 AM
A18: =TEXT(TIMEVALUE(LEFT(A17,FIND(" -",A17)-1))+TIME(0,30,0), "h:mm AM/PM") & " - " & TEXT(TIMEVALUE(MID(A17,FIND("- ",A17)+2,99))+TIME(0,30,0), "h:mm AM/PM") -> 8:30 AM - 9:00 AM
A19: =TEXT(TIMEVALUE(LEFT(A18,FIND(" -",A18)-1))+TIME(0,30,0), "h:mm AM/PM") & " - " & TEXT(TIMEVALUE(MID(A18,FIND("- ",A18)+2,99))+TIME(0,30,0), "h:mm AM/PM") -> 9:00 AM - 9:30 AM
... A43: =TEXT(TIMEVALUE(LEFT(A42,FIND(" -",A42)-1))+TIME(0,30,0), "h:mm AM/PM") & " - " & TEXT(TIMEVALUE(MID(A42,FIND("- ",A42)+2,99))+TIME(0,30,0), "h:mm AM/PM") -> 9:00 PM - 9:30 PM

Sheet Member 6 Name
A1: Step 1: Rename the sheet name with your name, for example 'Member 5 Name' to 'Your Name' | J1: Time Zone
A2: Step 2: Choose your time zone from yellow drop down box | J2: PST
A3: Step 3: Enter '1' in all 30-minute slots you're NOT available in orange area | J3: {=_xlfn.SWITCH(J2,"PST",0,"MST",1,"CST",2,"EST",3,0)} -> 0
A6: Time | B6: Monday | C6: Tuesday | D6: Wednesday | E6: Thursday | F6: Friday | G6: Saturday | H6: Sunday
A7: =TEXT(TIME(3,0,0)+$J$3/24,"h:mm AM/PM") & " - " & TEXT(TIME(3,30,0)+$J$3/24,"h:mm AM/PM") -> 3:00 AM - 3:30 AM
A8: =TEXT(TIMEVALUE(LEFT(A7,FIND(" -",A7)-1))+TIME(0,30,0), "h:mm AM/PM") & " - " & TEXT(TIMEVALUE(MID(A7,FIND("- ",A7)+2,99))+TIME(0,30,0), "h:mm AM/PM") -> 3:30 AM - 4:00 AM
A9: =TEXT(TIMEVALUE(LEFT(A8,FIND(" -",A8)-1))+TIME(0,30,0), "h:mm AM/PM") & " - " & TEXT(TIMEVALUE(MID(A8,FIND("- ",A8)+2,99))+TIME(0,30,0), "h:mm AM/PM") -> 4:00 AM - 4:30 AM
A10: =TEXT(TIMEVALUE(LEFT(A9,FIND(" -",A9)-1))+TIME(0,30,0), "h:mm AM/PM") & " - " & TEXT(TIMEVALUE(MID(A9,FIND("- ",A9)+2,99))+TIME(0,30,0), "h:mm AM/PM") -> 4:30 AM - 5:00 AM
A11: =TEXT(TIMEVALUE(LEFT(A10,FIND(" -",A10)-1))+TIME(0,30,0), "h:mm AM/PM") & " - " & TEXT(TIMEVALUE(MID(A10,FIND("- ",A10)+2,99))+TIME(0,30,0), "h:mm AM/PM") -> 5:00 AM - 5:30 AM
A12: =TEXT(TIMEVALUE(LEFT(A11,FIND(" -",A11)-1))+TIME(0,30,0), "h:mm AM/PM") & " - " & TEXT(TIMEVALUE(MID(A11,FIND("- ",A11)+2,99))+TIME(0,30,0), "h:mm AM/PM") -> 5:30 AM - 6:00 AM
A13: =TEXT(TIMEVALUE(LEFT(A12,FIND(" -",A12)-1))+TIME(0,30,0), "h:mm AM/PM") & " - " & TEXT(TIMEVALUE(MID(A12,FIND("- ",A12)+2,99))+TIME(0,30,0), "h:mm AM/PM") -> 6:00 AM - 6:30 AM
A14: =TEXT(TIMEVALUE(LEFT(A13,FIND(" -",A13)-1))+TIME(0,30,0), "h:mm AM/PM") & " - " & TEXT(TIMEVALUE(MID(A13,FIND("- ",A13)+2,99))+TIME(0,30,0), "h:mm AM/PM") -> 6:30 AM - 7:00 AM
A15: =TEXT(TIMEVALUE(LEFT(A14,FIND(" -",A14)-1))+TIME(0,30,0), "h:mm AM/PM") & " - " & TEXT(TIMEVALUE(MID(A14,FIND("- ",A14)+2,99))+TIME(0,30,0), "h:mm AM/PM") -> 7:00 AM - 7:30 AM
A16: =TEXT(TIMEVALUE(LEFT(A15,FIND(" -",A15)-1))+TIME(0,30,0), "h:mm AM/PM") & " - " & TEXT(TIMEVALUE(MID(A15,FIND("- ",A15)+2,99))+TIME(0,30,0), "h:mm AM/PM") -> 7:30 AM - 8:00 AM
A17: =TEXT(TIMEVALUE(LEFT(A16,FIND(" -",A16)-1))+TIME(0,30,0), "h:mm AM/PM") & " - " & TEXT(TIMEVALUE(MID(A16,FIND("- ",A16)+2,99))+TIME(0,30,0), "h:mm AM/PM") -> 8:00 AM - 8:30 AM
A18: =TEXT(TIMEVALUE(LEFT(A17,FIND(" -",A17)-1))+TIME(0,30,0), "h:mm AM/PM") & " - " & TEXT(TIMEVALUE(MID(A17,FIND("- ",A17)+2,99))+TIME(0,30,0), "h:mm AM/PM") -> 8:30 AM - 9:00 AM
A19: =TEXT(TIMEVALUE(LEFT(A18,FIND(" -",A18)-1))+TIME(0,30,0), "h:mm AM/PM") & " - " & TEXT(TIMEVALUE(MID(A18,FIND("- ",A18)+2,99))+TIME(0,30,0), "h:mm AM/PM") -> 9:00 AM - 9:30 AM
... A43: =TEXT(TIMEVALUE(LEFT(A42,FIND(" -",A42)-1))+TIME(0,30,0), "h:mm AM/PM") & " - " & TEXT(TIMEVALUE(MID(A42,FIND("- ",A42)+2,99))+TIME(0,30,0), "h:mm AM/PM") -> 9:00 PM - 9:30 PM

Sheet Member 7 Name
A1: Step 1: Rename the sheet name with your name, for example 'Member 5 Name' to 'Your Name' | J1: Time Zone
A2: Step 2: Choose your time zone from yellow drop down box | J2: PST
A3: Step 3: Enter '1' in all 30-minute slots you're NOT available in orange area | J3: {=_xlfn.SWITCH(J2,"PST",0,"MST",1,"CST",2,"EST",3,0)} -> 0
A6: Time | B6: Monday | C6: Tuesday | D6: Wednesday | E6: Thursday | F6: Friday | G6: Saturday | H6: Sunday
A7: =TEXT(TIME(3,0,0)+$J$3/24,"h:mm AM/PM") & " - " & TEXT(TIME(3,30,0)+$J$3/24,"h:mm AM/PM") -> 3:00 AM - 3:30 AM
A8: =TEXT(TIMEVALUE(LEFT(A7,FIND(" -",A7)-1))+TIME(0,30,0), "h:mm AM/PM") & " - " & TEXT(TIMEVALUE(MID(A7,FIND("- ",A7)+2,99))+TIME(0,30,0), "h:mm AM/PM") -> 3:30 AM - 4:00 AM
A9: =TEXT(TIMEVALUE(LEFT(A8,FIND(" -",A8)-1))+TIME(0,30,0), "h:mm AM/PM") & " - " & TEXT(TIMEVALUE(MID(A8,FIND("- ",A8)+2,99))+TIME(0,30,0), "h:mm AM/PM") -> 4:00 AM - 4:30 AM
A10: =TEXT(TIMEVALUE(LEFT(A9,FIND(" -",A9)-1))+TIME(0,30,0), "h:mm AM/PM") & " - " & TEXT(TIMEVALUE(MID(A9,FIND("- ",A9)+2,99))+TIME(0,30,0), "h:mm AM/PM") -> 4:30 AM - 5:00 AM
A11: =TEXT(TIMEVALUE(LEFT(A10,FIND(" -",A10)-1))+TIME(0,30,0), "h:mm AM/PM") & " - " & TEXT(TIMEVALUE(MID(A10,FIND("- ",A10)+2,99))+TIME(0,30,0), "h:mm AM/PM") -> 5:00 AM - 5:30 AM
A12: =TEXT(TIMEVALUE(LEFT(A11,FIND(" -",A11)-1))+TIME(0,30,0), "h:mm AM/PM") & " - " & TEXT(TIMEVALUE(MID(A11,FIND("- ",A11)+2,99))+TIME(0,30,0), "h:mm AM/PM") -> 5:30 AM - 6:00 AM
A13: =TEXT(TIMEVALUE(LEFT(A12,FIND(" -",A12)-1))+TIME(0,30,0), "h:mm AM/PM") & " - " & TEXT(TIMEVALUE(MID(A12,FIND("- ",A12)+2,99))+TIME(0,30,0), "h:mm AM/PM") -> 6:00 AM - 6:30 AM
A14: =TEXT(TIMEVALUE(LEFT(A13,FIND(" -",A13)-1))+TIME(0,30,0), "h:mm AM/PM") & " - " & TEXT(TIMEVALUE(MID(A13,FIND("- ",A13)+2,99))+TIME(0,30,0), "h:mm AM/PM") -> 6:30 AM - 7:00 AM
A15: =TEXT(TIMEVALUE(LEFT(A14,FIND(" -",A14)-1))+TIME(0,30,0), "h:mm AM/PM") & " - " & TEXT(TIMEVALUE(MID(A14,FIND("- ",A14)+2,99))+TIME(0,30,0), "h:mm AM/PM") -> 7:00 AM - 7:30 AM
A16: =TEXT(TIMEVALUE(LEFT(A15,FIND(" -",A15)-1))+TIME(0,30,0), "h:mm AM/PM") & " - " & TEXT(TIMEVALUE(MID(A15,FIND("- ",A15)+2,99))+TIME(0,30,0), "h:mm AM/PM") -> 7:30 AM - 8:00 AM
A17: =TEXT(TIMEVALUE(LEFT(A16,FIND(" -",A16)-1))+TIME(0,30,0), "h:mm AM/PM") & " - " & TEXT(TIMEVALUE(MID(A16,FIND("- ",A16)+2,99))+TIME(0,30,0), "h:mm AM/PM") -> 8:00 AM - 8:30 AM
A18: =TEXT(TIMEVALUE(LEFT(A17,FIND(" -",A17)-1))+TIME(0,30,0), "h:mm AM/PM") & " - " & TEXT(TIMEVALUE(MID(A17,FIND("- ",A17)+2,99))+TIME(0,30,0), "h:mm AM/PM") -> 8:30 AM - 9:00 AM
A19: =TEXT(TIMEVALUE(LEFT(A18,FIND(" -",A18)-1))+TIME(0,30,0), "h:mm AM/PM") & " - " & TEXT(TIMEVALUE(MID(A18,FIND("- ",A18)+2,99))+TIME(0,30,0), "h:mm AM/PM") -> 9:00 AM - 9:30 AM
... A43: =TEXT(TIMEVALUE(LEFT(A42,FIND(" -",A42)-1))+TIME(0,30,0), "h:mm AM/PM") & " - " & TEXT(TIMEVALUE(MID(A42,FIND("- ",A42)+2,99))+TIME(0,30,0), "h:mm AM/PM") -> 9:00 PM - 9:30 PM

Sheet Team Availability
A1: Step 1. Choose your time zone from yellow drop down box | J1: Time Zone
J2: PST
A3: The darker the cell, the more people are available. Black cells mean all members are free to meet. | J3: {=_xlfn.SWITCH(J2,"PST",0,"MST",1,"CST",2,"EST",3,0)} -> 0
A6: Time | B6: Monday | C6: Tuesday | D6: Wednesday | E6: Thursday | F6: Friday | G6: Saturday | H6: Sunday
A7: =TEXT(TIME(3,0,0)+$J$3/24,"h:mm AM/PM") & " - " & TEXT(TIME(3,30,0)+$J$3/24,"h:mm AM/PM") -> 3:00 AM - 3:30 AM | B7: =IF(COUNTA('Aaron Reimer'!B7,'Sruti Dondapati'!B7,'Member 3 Name'!B7,'Member 4 Name'!B7,'Member 5 Name'!B7,'Member 6 Name'!B7,'Member 7 Name'!B7)=0,0,COUNTA('Aaron Reimer'!B7,'Sruti Dondapati'!B7,'Member 3 Name'!B7,'Member 4 Name'!B7,'Member 5 Name'!B7,'Member 6 Name'!B7,'Member 7 Name'!B7)) -> 2 | C7: =IF(COUNTA('Aaron Reimer'!C7,'Sruti Dondapati'!C7,'Member 3 Name'!C7,'Member 4 Name'!C7,'Member 5 Name'!C7,'Member 6 Name'!C7,'Member 7 Name'!C7)=0,0,COUNTA('Aaron Reimer'!C7,'Sruti Dondapati'!C7,'Member 3 Name'!C7,'Member 4 Name'!C7,'Member 5 Name'!C7,'Member 6 Name'!C7,'Member 7 Name'!C7)) -> 2 | D7: =IF(COUNTA('Aaron Reimer'!D7,'Sruti Dondapati'!D7,'Member 3 Name'!D7,'Member 4 Name'!D7,'Member 5 Name'!D7,'Member 6 Name'!D7,'Member 7 Name'!D7)=0,0,COUNTA('Aaron Reimer'!D7,'Sruti Dondapati'!D7,'Member 3 Name'!D7,'Member 4 Name'!D7,'Member 5 Name'!D7,'Member 6 Name'!D7,'Member 7 Name'!D7)) -> 2 | E7: =IF(COUNTA('Aaron Reimer'!E7,'Sruti Dondapati'!E7,'Member 3 Name'!E7,'Member 4 Name'!E7,'Member 5 Name'!E7,'Member 6 Name'!E7,'Member 7 Name'!E7)=0,0,COUNTA('Aaron Reimer'!E7,'Sruti Dondapati'!E7,'Member 3 Name'!E7,'Member 4 Name'!E7,'Member 5 Name'!E7,'Member 6 Name'!E7,'Member 7 Name'!E7)) -> 2 | F7: =IF(COUNTA('Aaron Reimer'!F7,'Sruti Dondapati'!F7,'Member 3 Name'!F7,'Member 4 Name'!F7,'Member 5 Name'!F7,'Member 6 Name'!F7,'Member 7 Name'!F7)=0,0,COUNTA('Aaron Reimer'!F7,'Sruti Dondapati'!F7,'Member 3 Name'!F7,'Member 4 Name'!F7,'Member 5 Name'!F7,'Member 6 Name'!F7,'Member 7 Name'!F7)) -> 2 | G7: =IF(COUNTA('Aaron Reimer'!G7,'Sruti Dondapati'!G7,'Member 3 Name'!G7,'Member 4 Name'!G7,'Member 5 Name'!G7,'Member 6 Name'!G7,'Member 7 Name'!G7)=0,0,COUNTA('Aaron Reimer'!G7,'Sruti Dondapati'!G7,'Member 3 Name'!G7,'Member 4 Name'!G7,'Member 5 Name'!G7,'Member 6 Name'!G7,'Member 7 Name'!G7)) -> 2 | H7: =IF(COUNTA('Aaron Reimer'!H7,'Sruti Dondapati'!H7,'Member 3 Name'!H7,'Member 4 Name'!H7,'Member 5 Name'!H7,'Member 6 Name'!H7,'Member 7 Name'!H7)=0,0,COUNTA('Aaron Reimer'!H7,'Sruti Dondapati'!H7,'Member 3 Name'!H7,'Member 4 Name'!H7,'Member 5 Name'!H7,'Member 6 Name'!H7,'Member 7 Name'!H7)) -> 2
A8: =TEXT(TIMEVALUE(LEFT(A7,FIND(" -",A7)-1))+TIME(0,30,0), "h:mm AM/PM") & " - " & TEXT(TIMEVALUE(MID(A7,FIND("- ",A7)+2,99))+TIME(0,30,0), "h:mm AM/PM") -> 3:30 AM - 4:00 AM | B8: =IF(COUNTA('Aaron Reimer'!B8,'Sruti Dondapati'!B8,'Member 3 Name'!B8,'Member 4 Name'!B8,'Member 5 Name'!B8,'Member 6 Name'!B8,'Member 7 Name'!B8)=0,0,COUNTA('Aaron Reimer'!B8,'Sruti Dondapati'!B8,'Member 3 Name'!B8,'Member 4 Name'!B8,'Member 5 Name'!B8,'Member 6 Name'!B8,'Member 7 Name'!B8)) -> 2 | C8: =IF(COUNTA('Aaron Reimer'!C8,'Sruti Dondapati'!C8,'Member 3 Name'!C8,'Member 4 Name'!C8,'Member 5 Name'!C8,'Member 6 Name'!C8,'Member 7 Name'!C8)=0,0,COUNTA('Aaron Reimer'!C8,'Sruti Dondapati'!C8,'Member 3 Name'!C8,'Member 4 Name'!C8,'Member 5 Name'!C8,'Member 6 Name'!C8,'Member 7 Name'!C8)) -> 2 | D8: =IF(COUNTA('Aaron Reimer'!D8,'Sruti Dondapati'!D8,'Member 3 Name'!D8,'Member 4 Name'!D8,'Member 5 Name'!D8,'Member 6 Name'!D8,'Member 7 Name'!D8)=0,0,COUNTA('Aaron Reimer'!D8,'Sruti Dondapati'!D8,'Member 3 Name'!D8,'Member 4 Name'!D8,'Member 5 Name'!D8,'Member 6 Name'!D8,'Member 7 Name'!D8)) -> 2 | E8: =IF(COUNTA('Aaron Reimer'!E8,'Sruti Dondapati'!E8,'Member 3 Name'!E8,'Member 4 Name'!E8,'Member 5 Name'!E8,'Member 6 Name'!E8,'Member 7 Name'!E8)=0,0,COUNTA('Aaron Reimer'!E8,'Sruti Dondapati'!E8,'Member 3 Name'!E8,'Member 4 Name'!E8,'Member 5 Name'!E8,'Member 6 Name'!E8,'Member 7 Name'!E8)) -> 2 | F8: =IF(COUNTA('Aaron Reimer'!F8,'Sruti Dondapati'!F8,'Member 3 Name'!F8,'Member 4 Name'!F8,'Member 5 Name'!F8,'Member 6 Name'!F8,'Member 7 Name'!F8)=0,0,COUNTA('Aaron Reimer'!F8,'Sruti Dondapati'!F8,'Member 3 Name'!F8,'Member 4 Name'!F8,'Member 5 Name'!F8,'Member 6 Name'!F8,'Member 7 Name'!F8)) -> 2 | G8: =IF(COUNTA('Aaron Reimer'!G8,'Sruti Dondapati'!G8,'Member 3 Name'!G8,'Member 4 Name'!G8,'Member 5 Name'!G8,'Member 6 Name'!G8,'Member 7 Name'!G8)=0,0,COUNTA('Aaron Reimer'!G8,'Sruti Dondapati'!G8,'Member 3 Name'!G8,'Member 4 Name'!G8,'Member 5 Name'!G8,'Member 6 Name'!G8,'Member 7 Name'!G8)) -> 2 | H8: =IF(COUNTA('Aaron Reimer'!H8,'Sruti Dondapati'!H8,'Member 3 Name'!H8,'Member 4 Name'!H8,'Member 5 Name'!H8,'Member 6 Name'!H8,'Member 7 Name'!H8)=0,0,COUNTA('Aaron Reimer'!H8,'Sruti Dondapati'!H8,'Member 3 Name'!H8,'Member 4 Name'!H8,'Member 5 Name'!H8,'Member 6 Name'!H8,'Member 7 Name'!H8)) -> 2
A9: =TEXT(TIMEVALUE(LEFT(A8,FIND(" -",A8)-1))+TIME(0,30,0), "h:mm AM/PM") & " - " & TEXT(TIMEVALUE(MID(A8,FIND("- ",A8)+2,99))+TIME(0,30,0), "h:mm AM/PM") -> 4:00 AM - 4:30 AM | B9: =IF(COUNTA('Aaron Reimer'!B9,'Sruti Dondapati'!B9,'Member 3 Name'!B9,'Member 4 Name'!B9,'Member 5 Name'!B9,'Member 6 Name'!B9,'Member 7 Name'!B9)=0,0,COUNTA('Aaron Reimer'!B9,'Sruti Dondapati'!B9,'Member 3 Name'!B9,'Member 4 Name'!B9,'Member 5 Name'!B9,'Member 6 Name'!B9,'Member 7 Name'!B9)) -> 2 | C9: =IF(COUNTA('Aaron Reimer'!C9,'Sruti Dondapati'!C9,'Member 3 Name'!C9,'Member 4 Name'!C9,'Member 5 Name'!C9,'Member 6 Name'!C9,'Member 7 Name'!C9)=0,0,COUNTA('Aaron Reimer'!C9,'Sruti Dondapati'!C9,'Member 3 Name'!C9,'Member 4 Name'!C9,'Member 5 Name'!C9,'Member 6 Name'!C9,'Member 7 Name'!C9)) -> 2 | D9: =IF(COUNTA('Aaron Reimer'!D9,'Sruti Dondapati'!D9,'Member 3 Name'!D9,'Member 4 Name'!D9,'Member 5 Name'!D9,'Member 6 Name'!D9,'Member 7 Name'!D9)=0,0,COUNTA('Aaron Reimer'!D9,'Sruti Dondapati'!D9,'Member 3 Name'!D9,'Member 4 Name'!D9,'Member 5 Name'!D9,'Member 6 Name'!D9,'Member 7 Name'!D9)) -> 2 | E9: =IF(COUNTA('Aaron Reimer'!E9,'Sruti Dondapati'!E9,'Member 3 Name'!E9,'Member 4 Name'!E9,'Member 5 Name'!E9,'Member 6 Name'!E9,'Member 7 Name'!E9)=0,0,COUNTA('Aaron Reimer'!E9,'Sruti Dondapati'!E9,'Member 3 Name'!E9,'Member 4 Name'!E9,'Member 5 Name'!E9,'Member 6 Name'!E9,'Member 7 Name'!E9)) -> 2 | F9: =IF(COUNTA('Aaron Reimer'!F9,'Sruti Dondapati'!F9,'Member 3 Name'!F9,'Member 4 Name'!F9,'Member 5 Name'!F9,'Member 6 Name'!F9,'Member 7 Name'!F9)=0,0,COUNTA('Aaron Reimer'!F9,'Sruti Dondapati'!F9,'Member 3 Name'!F9,'Member 4 Name'!F9,'Member 5 Name'!F9,'Member 6 Name'!F9,'Member 7 Name'!F9)) -> 2 | G9: =IF(COUNTA('Aaron Reimer'!G9,'Sruti Dondapati'!G9,'Member 3 Name'!G9,'Member 4 Name'!G9,'Member 5 Name'!G9,'Member 6 Name'!G9,'Member 7 Name'!G9)=0,0,COUNTA('Aaron Reimer'!G9,'Sruti Dondapati'!G9,'Member 3 Name'!G9,'Member 4 Name'!G9,'Member 5 Name'!G9,'Member 6 Name'!G9,'Member 7 Name'!G9)) -> 2 | H9: =IF(COUNTA('Aaron Reimer'!H9,'Sruti Dondapati'!H9,'Member 3 Name'!H9,'Member 4 Name'!H9,'Member 5 Name'!H9,'Member 6 Name'!H9,'Member 7 Name'!H9)=0,0,COUNTA('Aaron Reimer'!H9,'Sruti Dondapati'!H9,'Member 3 Name'!H9,'Member 4 Name'!H9,'Member 5 Name'!H9,'Member 6 Name'!H9,'Member 7 Name'!H9)) -> 2
A10: =TEXT(TIMEVALUE(LEFT(A9,FIND(" -",A9)-1))+TIME(0,30,0), "h:mm AM/PM") & " - " & TEXT(TIMEVALUE(MID(A9,FIND("- ",A9)+2,99))+TIME(0,30,0), "h:mm AM/PM") -> 4:30 AM - 5:00 AM | B10: =IF(COUNTA('Aaron Reimer'!B10,'Sruti Dondapati'!B10,'Member 3 Name'!B10,'Member 4 Name'!B10,'Member 5 Name'!B10,'Member 6 Name'!B10,'Member 7 Name'!B10)=0,0,COUNTA('Aaron Reimer'!B10,'Sruti Dondapati'!B10,'Member 3 Name'!B10,'Member 4 Name'!B10,'Member 5 Name'!B10,'Member 6 Name'!B10,'Member 7 Name'!B10)) -> 2 | C10: =IF(COUNTA('Aaron Reimer'!C10,'Sruti Dondapati'!C10,'Member 3 Name'!C10,'Member 4 Name'!C10,'Member 5 Name'!C10,'Member 6 Name'!C10,'Member 7 Name'!C10)=0,0,COUNTA('Aaron Reimer'!C10,'Sruti Dondapati'!C10,'Member 3 Name'!C10,'Member 4 Name'!C10,'Member 5 Name'!C10,'Member 6 Name'!C10,'Member 7 Name'!C10)) -> 2 | D10: =IF(COUNTA('Aaron Reimer'!D10,'Sruti Dondapati'!D10,'Member 3 Name'!D10,'Member 4 Name'!D10,'Member 5 Name'!D10,'Member 6 Name'!D10,'Member 7 Name'!D10)=0,0,COUNTA('Aaron Reimer'!D10,'Sruti Dondapati'!D10,'Member 3 Name'!D10,'Member 4 Name'!D10,'Member 5 Name'!D10,'Member 6 Name'!D10,'Member 7 Name'!D10)) -> 2 | E10: =IF(COUNTA('Aaron Reimer'!E10,'Sruti Dondapati'!E10,'Member 3 Name'!E10,'Member 4 Name'!E10,'Member 5 Name'!E10,'Member 6 Name'!E10,'Member 7 Name'!E10)=0,0,COUNTA('Aaron Reimer'!E10,'Sruti Dondapati'!E10,'Member 3 Name'!E10,'Member 4 Name'!E10,'Member 5 Name'!E10,'Member 6 Name'!E10,'Member 7 Name'!E10)) -> 2 | F10: =IF(COUNTA('Aaron Reimer'!F10,'Sruti Dondapati'!F10,'Member 3 Name'!F10,'Member 4 Name'!F10,'Member 5 Name'!F10,'Member 6 Name'!F10,'Member 7 Name'!F10)=0,0,COUNTA('Aaron Reimer'!F10,'Sruti Dondapati'!F10,'Member 3 Name'!F10,'Member 4 Name'!F10,'Member 5 Name'!F10,'Member 6 Name'!F10,'Member 7 Name'!F10)) -> 2 | G10: =IF(COUNTA('Aaron Reimer'!G10,'Sruti Dondapati'!G10,'Member 3 Name'!G10,'Member 4 Name'!G10,'Member 5 Name'!G10,'Member 6 Name'!G10,'Member 7 Name'!G10)=0,0,COUNTA('Aaron Reimer'!G10,'Sruti Dondapati'!G10,'Member 3 Name'!G10,'Member 4 Name'!G10,'Member 5 Name'!G10,'Member 6 Name'!G10,'Member 7 Name'!G10)) -> 2 | H10: =IF(COUNTA('Aaron Reimer'!H10,'Sruti Dondapati'!H10,'Member 3 Name'!H10,'Member 4 Name'!H10,'Member 5 Name'!H10,'Member 6 Name'!H10,'Member 7 Name'!H10)=0,0,COUNTA('Aaron Reimer'!H10,'Sruti Dondapati'!H10,'Member 3 Name'!H10,'Member 4 Name'!H10,'Member 5 Name'!H10,'Member 6 Name'!H10,'Member 7 Name'!H10)) -> 2
A11: =TEXT(TIMEVALUE(LEFT(A10,FIND(" -",A10)-1))+TIME(0,30,0), "h:mm AM/PM") & " - " & TEXT(TIMEVALUE(MID(A10,FIND("- ",A10)+2,99))+TIME(0,30,0), "h:mm AM/PM") -> 5:00 AM - 5:30 AM | B11: =IF(COUNTA('Aaron Reimer'!B11,'Sruti Dondapati'!B11,'Member 3 Name'!B11,'Member 4 Name'!B11,'Member 5 Name'!B11,'Member 6 Name'!B11,'Member 7 Name'!B11)=0,0,COUNTA('Aaron Reimer'!B11,'Sruti Dondapati'!B11,'Member 3 Name'!B11,'Member 4 Name'!B11,'Member 5 Name'!B11,'Member 6 Name'!B11,'Member 7 Name'!B11)) -> 2 | C11: =IF(COUNTA('Aaron Reimer'!C11,'Sruti Dondapati'!C11,'Member 3 Name'!C11,'Member 4 Name'!C11,'Member 5 Name'!C11,'Member 6 Name'!C11,'Member 7 Name'!C11)=0,0,COUNTA('Aaron Reimer'!C11,'Sruti Dondapati'!C11,'Member 3 Name'!C11,'Member 4 Name'!C11,'Member 5 Name'!C11,'Member 6 Name'!C11,'Member 7 Name'!C11)) -> 2 | D11: =IF(COUNTA('Aaron Reimer'!D11,'Sruti Dondapati'!D11,'Member 3 Name'!D11,'Member 4 Name'!D11,'Member 5 Name'!D11,'Member 6 Name'!D11,'Member 7 Name'!D11)=0,0,COUNTA('Aaron Reimer'!D11,'Sruti Dondapati'!D11,'Member 3 Name'!D11,'Member 4 Name'!D11,'Member 5 Name'!D11,'Member 6 Name'!D11,'Member 7 Name'!D11)) -> 2 | E11: =IF(COUNTA('Aaron Reimer'!E11,'Sruti Dondapati'!E11,'Member 3 Name'!E11,'Member 4 Name'!E11,'Member 5 Name'!E11,'Member 6 Name'!E11,'Member 7 Name'!E11)=0,0,COUNTA('Aaron Reimer'!E11,'Sruti Dondapati'!E11,'Member 3 Name'!E11,'Member 4 Name'!E11,'Member 5 Name'!E11,'Member 6 Name'!E11,'Member 7 Name'!E11)) -> 2 | F11: =IF(COUNTA('Aaron Reimer'!F11,'Sruti Dondapati'!F11,'Member 3 Name'!F11,'Member 4 Name'!F11,'Member 5 Name'!F11,'Member 6 Name'!F11,'Member 7 Name'!F11)=0,0,COUNTA('Aaron Reimer'!F11,'Sruti Dondapati'!F11,'Member 3 Name'!F11,'Member 4 Name'!F11,'Member 5 Name'!F11,'Member 6 Name'!F11,'Member 7 Name'!F11)) -> 2 | G11: =IF(COUNTA('Aaron Reimer'!G11,'Sruti Dondapati'!G11,'Member 3 Name'!G11,'Member 4 Name'!G11,'Member 5 Name'!G11,'Member 6 Name'!G11,'Member 7 Name'!G11)=0,0,COUNTA('Aaron Reimer'!G11,'Sruti Dondapati'!G11,'Member 3 Name'!G11,'Member 4 Name'!G11,'Member 5 Name'!G11,'Member 6 Name'!G11,'Member 7 Name'!G11)) -> 2 | H11: =IF(COUNTA('Aaron Reimer'!H11,'Sruti Dondapati'!H11,'Member 3 Name'!H11,'Member 4 Name'!H11,'Member 5 Name'!H11,'Member 6 Name'!H11,'Member 7 Name'!H11)=0,0,COUNTA('Aaron Reimer'!H11,'Sruti Dondapati'!H11,'Member 3 Name'!H11,'Member 4 Name'!H11,'Member 5 Name'!H11,'Member 6 Name'!H11,'Member 7 Name'!H11)) -> 2
A12: =TEXT(TIMEVALUE(LEFT(A11,FIND(" -",A11)-1))+TIME(0,30,0), "h:mm AM/PM") & " - " & TEXT(TIMEVALUE(MID(A11,FIND("- ",A11)+2,99))+TIME(0,30,0), "h:mm AM/PM") -> 5:30 AM - 6:00 AM | B12: =IF(COUNTA('Aaron Reimer'!B12,'Sruti Dondapati'!B12,'Member 3 Name'!B12,'Member 4 Name'!B12,'Member 5 Name'!B12,'Member 6 Name'!B12,'Member 7 Name'!B12)=0,0,COUNTA('Aaron Reimer'!B12,'Sruti Dondapati'!B12,'Member 3 Name'!B12,'Member 4 Name'!B12,'Member 5 Name'!B12,'Member 6 Name'!B12,'Member 7 Name'!B12)) -> 2 | C12: =IF(COUNTA('Aaron Reimer'!C12,'Sruti Dondapati'!C12,'Member 3 Name'!C12,'Member 4 Name'!C12,'Member 5 Name'!C12,'Member 6 Name'!C12,'Member 7 Name'!C12)=0,0,COUNTA('Aaron Reimer'!C12,'Sruti Dondapati'!C12,'Member 3 Name'!C12,'Member 4 Name'!C12,'Member 5 Name'!C12,'Member 6 Name'!C12,'Member 7 Name'!C12)) -> 2 | D12: =IF(COUNTA('Aaron Reimer'!D12,'Sruti Dondapati'!D12,'Member 3 Name'!D12,'Member 4 Name'!D12,'Member 5 Name'!D12,'Member 6 Name'!D12,'Member 7 Name'!D12)=0,0,COUNTA('Aaron Reimer'!D12,'Sruti Dondapati'!D12,'Member 3 Name'!D12,'Member 4 Name'!D12,'Member 5 Name'!D12,'Member 6 Name'!D12,'Member 7 Name'!D12)) -> 2 | E12: =IF(COUNTA('Aaron Reimer'!E12,'Sruti Dondapati'!E12,'Member 3 Name'!E12,'Member 4 Name'!E12,'Member 5 Name'!E12,'Member 6 Name'!E12,'Member 7 Name'!E12)=0,0,COUNTA('Aaron Reimer'!E12,'Sruti Dondapati'!E12,'Member 3 Name'!E12,'Member 4 Name'!E12,'Member 5 Name'!E12,'Member 6 Name'!E12,'Member 7 Name'!E12)) -> 2 | F12: =IF(COUNTA('Aaron Reimer'!F12,'Sruti Dondapati'!F12,'Member 3 Name'!F12,'Member 4 Name'!F12,'Member 5 Name'!F12,'Member 6 Name'!F12,'Member 7 Name'!F12)=0,0,COUNTA('Aaron Reimer'!F12,'Sruti Dondapati'!F12,'Member 3 Name'!F12,'Member 4 Name'!F12,'Member 5 Name'!F12,'Member 6 Name'!F12,'Member 7 Name'!F12)) -> 2 | G12: =IF(COUNTA('Aaron Reimer'!G12,'Sruti Dondapati'!G12,'Member 3 Name'!G12,'Member 4 Name'!G12,'Member 5 Name'!G12,'Member 6 Name'!G12,'Member 7 Name'!G12)=0,0,COUNTA('Aaron Reimer'!G12,'Sruti Dondapati'!G12,'Member 3 Name'!G12,'Member 4 Name'!G12,'Member 5 Name'!G12,'Member 6 Name'!G12,'Member 7 Name'!G12)) -> 2 | H12: =IF(COUNTA('Aaron Reimer'!H12,'Sruti Dondapati'!H12,'Member 3 Name'!H12,'Member 4 Name'!H12,'Member 5 Name'!H12,'Member 6 Name'!H12,'Member 7 Name'!H12)=0,0,COUNTA('Aaron Reimer'!H12,'Sruti Dondapati'!H12,'Member 3 Name'!H12,'Member 4 Name'!H12,'Member 5 Name'!H12,'Member 6 Name'!H12,'Member 7 Name'!H12)) -> 2
A13: =TEXT(TIMEVALUE(LEFT(A12,FIND(" -",A12)-1))+TIME(0,30,0), "h:mm AM/PM") & " - " & TEXT(TIMEVALUE(MID(A12,FIND("- ",A12)+2,99))+TIME(0,30,0), "h:mm AM/PM") -> 6:00 AM - 6:30 AM | B13: =IF(COUNTA('Aaron Reimer'!B13,'Sruti Dondapati'!B13,'Member 3 Name'!B13,'Member 4 Name'!B13,'Member 5 Name'!B13,'Member 6 Name'!B13,'Member 7 Name'!B13)=0,0,COUNTA('Aaron Reimer'!B13,'Sruti Dondapati'!B13,'Member 3 Name'!B13,'Member 4 Name'!B13,'Member 5 Name'!B13,'Member 6 Name'!B13,'Member 7 Name'!B13)) -> 2 | C13: =IF(COUNTA('Aaron Reimer'!C13,'Sruti Dondapati'!C13,'Member 3 Name'!C13,'Member 4 Name'!C13,'Member 5 Name'!C13,'Member 6 Name'!C13,'Member 7 Name'!C13)=0,0,COUNTA('Aaron Reimer'!C13,'Sruti Dondapati'!C13,'Member 3 Name'!C13,'Member 4 Name'!C13,'Member 5 Name'!C13,'Member 6 Name'!C13,'Member 7 Name'!C13)) -> 2 | D13: =IF(COUNTA('Aaron Reimer'!D13,'Sruti Dondapati'!D13,'Member 3 Name'!D13,'Member 4 Name'!D13,'Member 5 Name'!D13,'Member 6 Name'!D13,'Member 7 Name'!D13)=0,0,COUNTA('Aaron Reimer'!D13,'Sruti Dondapati'!D13,'Member 3 Name'!D13,'Member 4 Name'!D13,'Member 5 Name'!D13,'Member 6 Name'!D13,'Member 7 Name'!D13)) -> 2 | E13: =IF(COUNTA('Aaron Reimer'!E13,'Sruti Dondapati'!E13,'Member 3 Name'!E13,'Member 4 Name'!E13,'Member 5 Name'!E13,'Member 6 Name'!E13,'Member 7 Name'!E13)=0,0,COUNTA('Aaron Reimer'!E13,'Sruti Dondapati'!E13,'Member 3 Name'!E13,'Member 4 Name'!E13,'Member 5 Name'!E13,'Member 6 Name'!E13,'Member 7 Name'!E13)) -> 2 | F13: =IF(COUNTA('Aaron Reimer'!F13,'Sruti Dondapati'!F13,'Member 3 Name'!F13,'Member 4 Name'!F13,'Member 5 Name'!F13,'Member 6 Name'!F13,'Member 7 Name'!F13)=0,0,COUNTA('Aaron Reimer'!F13,'Sruti Dondapati'!F13,'Member 3 Name'!F13,'Member 4 Name'!F13,'Member 5 Name'!F13,'Member 6 Name'!F13,'Member 7 Name'!F13)) -> 2 | G13: =IF(COUNTA('Aaron Reimer'!G13,'Sruti Dondapati'!G13,'Member 3 Name'!G13,'Member 4 Name'!G13,'Member 5 Name'!G13,'Member 6 Name'!G13,'Member 7 Name'!G13)=0,0,COUNTA('Aaron Reimer'!G13,'Sruti Dondapati'!G13,'Member 3 Name'!G13,'Member 4 Name'!G13,'Member 5 Name'!G13,'Member 6 Name'!G13,'Member 7 Name'!G13)) -> 2 | H13: =IF(COUNTA('Aaron Reimer'!H13,'Sruti Dondapati'!H13,'Member 3 Name'!H13,'Member 4 Name'!H13,'Member 5 Name'!H13,'Member 6 Name'!H13,'Member 7 Name'!H13)=0,0,COUNTA('Aaron Reimer'!H13,'Sruti Dondapati'!H13,'Member 3 Name'!H13,'Member 4 Name'!H13,'Member 5 Name'!H13,'Member 6 Name'!H13,'Member 7 Name'!H13)) -> 2
A14: =TEXT(TIMEVALUE(LEFT(A13,FIND(" -",A13)-1))+TIME(0,30,0), "h:mm AM/PM") & " - " & TEXT(TIMEVALUE(MID(A13,FIND("- ",A13)+2,99))+TIME(0,30,0), "h:mm AM/PM") -> 6:30 AM - 7:00 AM | B14: =IF(COUNTA('Aaron Reimer'!B14,'Sruti Dondapati'!B14,'Member 3 Name'!B14,'Member 4 Name'!B14,'Member 5 Name'!B14,'Member 6 Name'!B14,'Member 7 Name'!B14)=0,0,COUNTA('Aaron Reimer'!B14,'Sruti Dondapati'!B14,'Member 3 Name'!B14,'Member 4 Name'!B14,'Member 5 Name'!B14,'Member 6 Name'!B14,'Member 7 Name'!B14)) -> 2 | C14: =IF(COUNTA('Aaron Reimer'!C14,'Sruti Dondapati'!C14,'Member 3 Name'!C14,'Member 4 Name'!C14,'Member 5 Name'!C14,'Member 6 Name'!C14,'Member 7 Name'!C14)=0,0,COUNTA('Aaron Reimer'!C14,'Sruti Dondapati'!C14,'Member 3 Name'!C14,'Member 4 Name'!C14,'Member 5 Name'!C14,'Member 6 Name'!C14,'Member 7 Name'!C14)) -> 2 | D14: =IF(COUNTA('Aaron Reimer'!D14,'Sruti Dondapati'!D14,'Member 3 Name'!D14,'Member 4 Name'!D14,'Member 5 Name'!D14,'Member 6 Name'!D14,'Member 7 Name'!D14)=0,0,COUNTA('Aaron Reimer'!D14,'Sruti Dondapati'!D14,'Member 3 Name'!D14,'Member 4 Name'!D14,'Member 5 Name'!D14,'Member 6 Name'!D14,'Member 7 Name'!D14)) -> 2 | E14: =IF(COUNTA('Aaron Reimer'!E14,'Sruti Dondapati'!E14,'Member 3 Name'!E14,'Member 4 Name'!E14,'Member 5 Name'!E14,'Member 6 Name'!E14,'Member 7 Name'!E14)=0,0,COUNTA('Aaron Reimer'!E14,'Sruti Dondapati'!E14,'Member 3 Name'!E14,'Member 4 Name'!E14,'Member 5 Name'!E14,'Member 6 Name'!E14,'Member 7 Name'!E14)) -> 2 | F14: =IF(COUNTA('Aaron Reimer'!F14,'Sruti Dondapati'!F14,'Member 3 Name'!F14,'Member 4 Name'!F14,'Member 5 Name'!F14,'Member 6 Name'!F14,'Member 7 Name'!F14)=0,0,COUNTA('Aaron Reimer'!F14,'Sruti Dondapati'!F14,'Member 3 Name'!F14,'Member 4 Name'!F14,'Member 5 Name'!F14,'Member 6 Name'!F14,'Member 7 Name'!F14)) -> 2 | G14: =IF(COUNTA('Aaron Reimer'!G14,'Sruti Dondapati'!G14,'Member 3 Name'!G14,'Member 4 Name'!G14,'Member 5 Name'!G14,'Member 6 Name'!G14,'Member 7 Name'!G14)=0,0,COUNTA('Aaron Reimer'!G14,'Sruti Dondapati'!G14,'Member 3 Name'!G14,'Member 4 Name'!G14,'Member 5 Name'!G14,'Member 6 Name'!G14,'Member 7 Name'!G14)) -> 2 | H14: =IF(COUNTA('Aaron Reimer'!H14,'Sruti Dondapati'!H14,'Member 3 Name'!H14,'Member 4 Name'!H14,'Member 5 Name'!H14,'Member 6 Name'!H14,'Member 7 Name'!H14)=0,0,COUNTA('Aaron Reimer'!H14,'Sruti Dondapati'!H14,'Member 3 Name'!H14,'Member 4 Name'!H14,'Member 5 Name'!H14,'Member 6 Name'!H14,'Member 7 Name'!H14)) -> 2
A15: =TEXT(TIMEVALUE(LEFT(A14,FIND(" -",A14)-1))+TIME(0,30,0), "h:mm AM/PM") & " - " & TEXT(TIMEVALUE(MID(A14,FIND("- ",A14)+2,99))+TIME(0,30,0), "h:mm AM/PM") -> 7:00 AM - 7:30 AM | B15: =IF(COUNTA('Aaron Reimer'!B15,'Sruti Dondapati'!B15,'Member 3 Name'!B15,'Member 4 Name'!B15,'Member 5 Name'!B15,'Member 6 Name'!B15,'Member 7 Name'!B15)=0,0,COUNTA('Aaron Reimer'!B15,'Sruti Dondapati'!B15,'Member 3 Name'!B15,'Member 4 Name'!B15,'Member 5 Name'!B15,'Member 6 Name'!B15,'Member 7 Name'!B15)) -> 2 | C15: =IF(COUNTA('Aaron Reimer'!C15,'Sruti Dondapati'!C15,'Member 3 Name'!C15,'Member 4 Name'!C15,'Member 5 Name'!C15,'Member 6 Name'!C15,'Member 7 Name'!C15)=0,0,COUNTA('Aaron Reimer'!C15,'Sruti Dondapati'!C15,'Member 3 Name'!C15,'Member 4 Name'!C15,'Member 5 Name'!C15,'Member 6 Name'!C15,'Member 7 Name'!C15)) -> 2 | D15: =IF(COUNTA('Aaron Reimer'!D15,'Sruti Dondapati'!D15,'Member 3 Name'!D15,'Member 4 Name'!D15,'Member 5 Name'!D15,'Member 6 Name'!D15,'Member 7 Name'!D15)=0,0,COUNTA('Aaron Reimer'!D15,'Sruti Dondapati'!D15,'Member 3 Name'!D15,'Member 4 Name'!D15,'Member 5 Name'!D15,'Member 6 Name'!D15,'Member 7 Name'!D15)) -> 2 | E15: =IF(COUNTA('Aaron Reimer'!E15,'Sruti Dondapati'!E15,'Member 3 Name'!E15,'Member 4 Name'!E15,'Member 5 Name'!E15,'Member 6 Name'!E15,'Member 7 Name'!E15)=0,0,COUNTA('Aaron Reimer'!E15,'Sruti Dondapati'!E15,'Member 3 Name'!E15,'Member 4 Name'!E15,'Member 5 Name'!E15,'Member 6 Name'!E15,'Member 7 Name'!E15)) -> 2 | F15: =IF(COUNTA('Aaron Reimer'!F15,'Sruti Dondapati'!F15,'Member 3 Name'!F15,'Member 4 Name'!F15,'Member 5 Name'!F15,'Member 6 Name'!F15,'Member 7 Name'!F15)=0,0,COUNTA('Aaron Reimer'!F15,'Sruti Dondapati'!F15,'Member 3 Name'!F15,'Member 4 Name'!F15,'Member 5 Name'!F15,'Member 6 Name'!F15,'Member 7 Name'!F15)) -> 2 | G15: =IF(COUNTA('Aaron Reimer'!G15,'Sruti Dondapati'!G15,'Member 3 Name'!G15,'Member 4 Name'!G15,'Member 5 Name'!G15,'Member 6 Name'!G15,'Member 7 Name'!G15)=0,0,COUNTA('Aaron Reimer'!G15,'Sruti Dondapati'!G15,'Member 3 Name'!G15,'Member 4 Name'!G15,'Member 5 Name'!G15,'Member 6 Name'!G15,'Member 7 Name'!G15)) -> 2 | H15: =IF(COUNTA('Aaron Reimer'!H15,'Sruti Dondapati'!H15,'Member 3 Name'!H15,'Member 4 Name'!H15,'Member 5 Name'!H15,'Member 6 Name'!H15,'Member 7 Name'!H15)=0,0,COUNTA('Aaron Reimer'!H15,'Sruti Dondapati'!H15,'Member 3 Name'!H15,'Member 4 Name'!H15,'Member 5 Name'!H15,'Member 6 Name'!H15,'Member 7 Name'!H15)) -> 2
A16: =TEXT(TIMEVALUE(LEFT(A15,FIND(" -",A15)-1))+TIME(0,30,0), "h:mm AM/PM") & " - " & TEXT(TIMEVALUE(MID(A15,FIND("- ",A15)+2,99))+TIME(0,30,0), "h:mm AM/PM") -> 7:30 AM - 8:00 AM | B16: =IF(COUNTA('Aaron Reimer'!B16,'Sruti Dondapati'!B16,'Member 3 Name'!B16,'Member 4 Name'!B16,'Member 5 Name'!B16,'Member 6 Name'!B16,'Member 7 Name'!B16)=0,0,COUNTA('Aaron Reimer'!B16,'Sruti Dondapati'!B16,'Member 3 Name'!B16,'Member 4 Name'!B16,'Member 5 Name'!B16,'Member 6 Name'!B16,'Member 7 Name'!B16)) -> 2 | C16: =IF(COUNTA('Aaron Reimer'!C16,'Sruti Dondapati'!C16,'Member 3 Name'!C16,'Member 4 Name'!C16,'Member 5 Name'!C16,'Member 6 Name'!C16,'Member 7 Name'!C16)=0,0,COUNTA('Aaron Reimer'!C16,'Sruti Dondapati'!C16,'Member 3 Name'!C16,'Member 4 Name'!C16,'Member 5 Name'!C16,'Member 6 Name'!C16,'Member 7 Name'!C16)) -> 2 | D16: =IF(COUNTA('Aaron Reimer'!D16,'Sruti Dondapati'!D16,'Member 3 Name'!D16,'Member 4 Name'!D16,'Member 5 Name'!D16,'Member 6 Name'!D16,'Member 7 Name'!D16)=0,0,COUNTA('Aaron Reimer'!D16,'Sruti Dondapati'!D16,'Member 3 Name'!D16,'Member 4 Name'!D16,'Member 5 Name'!D16,'Member 6 Name'!D16,'Member 7 Name'!D16)) -> 2 | E16: =IF(COUNTA('Aaron Reimer'!E16,'Sruti Dondapati'!E16,'Member 3 Name'!E16,'Member 4 Name'!E16,'Member 5 Name'!E16,'Member 6 Name'!E16,'Member 7 Name'!E16)=0,0,COUNTA('Aaron Reimer'!E16,'Sruti Dondapati'!E16,'Member 3 Name'!E16,'Member 4 Name'!E16,'Member 5 Name'!E16,'Member 6 Name'!E16,'Member 7 Name'!E16)) -> 2 | F16: =IF(COUNTA('Aaron Reimer'!F16,'Sruti Dondapati'!F16,'Member 3 Name'!F16,'Member 4 Name'!F16,'Member 5 Name'!F16,'Member 6 Name'!F16,'Member 7 Name'!F16)=0,0,COUNTA('Aaron Reimer'!F16,'Sruti Dondapati'!F16,'Member 3 Name'!F16,'Member 4 Name'!F16,'Member 5 Name'!F16,'Member 6 Name'!F16,'Member 7 Name'!F16)) -> 2 | G16: =IF(COUNTA('Aaron Reimer'!G16,'Sruti Dondapati'!G16,'Member 3 Name'!G16,'Member 4 Name'!G16,'Member 5 Name'!G16,'Member 6 Name'!G16,'Member 7 Name'!G16)=0,0,COUNTA('Aaron Reimer'!G16,'Sruti Dondapati'!G16,'Member 3 Name'!G16,'Member 4 Name'!G16,'Member 5 Name'!G16,'Member 6 Name'!G16,'Member 7 Name'!G16)) -> 2 | H16: =IF(COUNTA('Aaron Reimer'!H16,'Sruti Dondapati'!H16,'Member 3 Name'!H16,'Member 4 Name'!H16,'Member 5 Name'!H16,'Member 6 Name'!H16,'Member 7 Name'!H16)=0,0,COUNTA('Aaron Reimer'!H16,'Sruti Dondapati'!H16,'Member 3 Name'!H16,'Member 4 Name'!H16,'Member 5 Name'!H16,'Member 6 Name'!H16,'Member 7 Name'!H16)) -> 2
A17: =TEXT(TIMEVALUE(LEFT(A16,FIND(" -",A16)-1))+TIME(0,30,0), "h:mm AM/PM") & " - " & TEXT(TIMEVALUE(MID(A16,FIND("- ",A16)+2,99))+TIME(0,30,0), "h:mm AM/PM") -> 8:00 AM - 8:30 AM | B17: =IF(COUNTA('Aaron Reimer'!B17,'Sruti Dondapati'!B17,'Member 3 Name'!B17,'Member 4 Name'!B17,'Member 5 Name'!B17,'Member 6 Name'!B17,'Member 7 Name'!B17)=0,0,COUNTA('Aaron Reimer'!B17,'Sruti Dondapati'!B17,'Member 3 Name'!B17,'Member 4 Name'!B17,'Member 5 Name'!B17,'Member 6 Name'!B17,'Member 7 Name'!B17)) -> 2 | C17: =IF(COUNTA('Aaron Reimer'!C17,'Sruti Dondapati'!C17,'Member 3 Name'!C17,'Member 4 Name'!C17,'Member 5 Name'!C17,'Member 6 Name'!C17,'Member 7 Name'!C17)=0,0,COUNTA('Aaron Reimer'!C17,'Sruti Dondapati'!C17,'Member 3 Name'!C17,'Member 4 Name'!C17,'Member 5 Name'!C17,'Member 6 Name'!C17,'Member 7 Name'!C17)) -> 2 | D17: =IF(COUNTA('Aaron Reimer'!D17,'Sruti Dondapati'!D17,'Member 3 Name'!D17,'Member 4 Name'!D17,'Member 5 Name'!D17,'Member 6 Name'!D17,'Member 7 Name'!D17)=0,0,COUNTA('Aaron Reimer'!D17,'Sruti Dondapati'!D17,'Member 3 Name'!D17,'Member 4 Name'!D17,'Member 5 Name'!D17,'Member 6 Name'!D17,'Member 7 Name'!D17)) -> 2 | E17: =IF(COUNTA('Aaron Reimer'!E17,'Sruti Dondapati'!E17,'Member 3 Name'!E17,'Member 4 Name'!E17,'Member 5 Name'!E17,'Member 6 Name'!E17,'Member 7 Name'!E17)=0,0,COUNTA('Aaron Reimer'!E17,'Sruti Dondapati'!E17,'Member 3 Name'!E17,'Member 4 Name'!E17,'Member 5 Name'!E17,'Member 6 Name'!E17,'Member 7 Name'!E17)) -> 2 | F17: =IF(COUNTA('Aaron Reimer'!F17,'Sruti Dondapati'!F17,'Member 3 Name'!F17,'Member 4 Name'!F17,'Member 5 Name'!F17,'Member 6 Name'!F17,'Member 7 Name'!F17)=0,0,COUNTA('Aaron Reimer'!F17,'Sruti Dondapati'!F17,'Member 3 Name'!F17,'Member 4 Name'!F17,'Member 5 Name'!F17,'Member 6 Name'!F17,'Member 7 Name'!F17)) -> 2 | G17: =IF(COUNTA('Aaron Reimer'!G17,'Sruti Dondapati'!G17,'Member 3 Name'!G17,'Member 4 Name'!G17,'Member 5 Name'!G17,'Member 6 Name'!G17,'Member 7 Name'!G17)=0,0,COUNTA('Aaron Reimer'!G17,'Sruti Dondapati'!G17,'Member 3 Name'!G17,'Member 4 Name'!G17,'Member 5 Name'!G17,'Member 6 Name'!G17,'Member 7 Name'!G17)) -> 2 | H17: =IF(COUNTA('Aaron Reimer'!H17,'Sruti Dondapati'!H17,'Member 3 Name'!H17,'Member 4 Name'!H17,'Member 5 Name'!H17,'Member 6 Name'!H17,'Member 7 Name'!H17)=0,0,COUNTA('Aaron Reimer'!H17,'Sruti Dondapati'!H17,'Member 3 Name'!H17,'Member 4 Name'!H17,'Member 5 Name'!H17,'Member 6 Name'!H17,'Member 7 Name'!H17)) -> 2
A18: =TEXT(TIMEVALUE(LEFT(A17,FIND(" -",A17)-1))+TIME(0,30,0), "h:mm AM/PM") & " - " & TEXT(TIMEVALUE(MID(A17,FIND("- ",A17)+2,99))+TIME(0,30,0), "h:mm AM/PM") -> 8:30 AM - 9:00 AM | B18: =IF(COUNTA('Aaron Reimer'!B18,'Sruti Dondapati'!B18,'Member 3 Name'!B18,'Member 4 Name'!B18,'Member 5 Name'!B18,'Member 6 Name'!B18,'Member 7 Name'!B18)=0,0,COUNTA('Aaron Reimer'!B18,'Sruti Dondapati'!B18,'Member 3 Name'!B18,'Member 4 Name'!B18,'Member 5 Name'!B18,'Member 6 Name'!B18,'Member 7 Name'!B18)) -> 2 | C18: =IF(COUNTA('Aaron Reimer'!C18,'Sruti Dondapati'!C18,'Member 3 Name'!C18,'Member 4 Name'!C18,'Member 5 Name'!C18,'Member 6 Name'!C18,'Member 7 Name'!C18)=0,0,COUNTA('Aaron Reimer'!C18,'Sruti Dondapati'!C18,'Member 3 Name'!C18,'Member 4 Name'!C18,'Member 5 Name'!C18,'Member 6 Name'!C18,'Member 7 Name'!C18)) -> 2 | D18: =IF(COUNTA('Aaron Reimer'!D18,'Sruti Dondapati'!D18,'Member 3 Name'!D18,'Member 4 Name'!D18,'Member 5 Name'!D18,'Member 6 Name'!D18,'Member 7 Name'!D18)=0,0,COUNTA('Aaron Reimer'!D18,'Sruti Dondapati'!D18,'Member 3 Name'!D18,'Member 4 Name'!D18,'Member 5 Name'!D18,'Member 6 Name'!D18,'Member 7 Name'!D18)) -> 2 | E18: =IF(COUNTA('Aaron Reimer'!E18,'Sruti Dondapati'!E18,'Member 3 Name'!E18,'Member 4 Name'!E18,'Member 5 Name'!E18,'Member 6 Name'!E18,'Member 7 Name'!E18)=0,0,COUNTA('Aaron Reimer'!E18,'Sruti Dondapati'!E18,'Member 3 Name'!E18,'Member 4 Name'!E18,'Member 5 Name'!E18,'Member 6 Name'!E18,'Member 7 Name'!E18)) -> 2 | F18: =IF(COUNTA('Aaron Reimer'!F18,'Sruti Dondapati'!F18,'Member 3 Name'!F18,'Member 4 Name'!F18,'Member 5 Name'!F18,'Member 6 Name'!F18,'Member 7 Name'!F18)=0,0,COUNTA('Aaron Reimer'!F18,'Sruti Dondapati'!F18,'Member 3 Name'!F18,'Member 4 Name'!F18,'Member 5 Name'!F18,'Member 6 Name'!F18,'Member 7 Name'!F18)) -> 2 | G18: =IF(COUNTA('Aaron Reimer'!G18,'Sruti Dondapati'!G18,'Member 3 Name'!G18,'Member 4 Name'!G18,'Member 5 Name'!G18,'Member 6 Name'!G18,'Member 7 Name'!G18)=0,0,COUNTA('Aaron Reimer'!G18,'Sruti Dondapati'!G18,'Member 3 Name'!G18,'Member 4 Name'!G18,'Member 5 Name'!G18,'Member 6 Name'!G18,'Member 7 Name'!G18)) -> 2 | H18: =IF(COUNTA('Aaron Reimer'!H18,'Sruti Dondapati'!H18,'Member 3 Name'!H18,'Member 4 Name'!H18,'Member 5 Name'!H18,'Member 6 Name'!H18,'Member 7 Name'!H18)=0,0,COUNTA('Aaron Reimer'!H18,'Sruti Dondapati'!H18,'Member 3 Name'!H18,'Member 4 Name'!H18,'Member 5 Name'!H18,'Member 6 Name'!H18,'Member 7 Name'!H18)) -> 2
